Workbook
Name Diagram_Ar: Resultatunderlag!#REF!:INDEX(Resultatunderlag!#REF!,Tidshorisont)
Name Diagram_FinKost: Resultatunderlag!$E$8:INDEX(Resultatunderlag!$E$8:$E$32,Tidshorisont)
Name Diagram_FinNytta: Resultatunderlag!$C$8:INDEX(Resultatunderlag!$C$8:$C$32,Tidshorisont)
Name Diagram_OmfKost: Resultatunderlag!$F$8:INDEX(Resultatunderlag!$F$8:$F$32,Tidshorisont)
Name Diagram_OmfNytta: Resultatunderlag!$D$8:INDEX(Resultatunderlag!$D$8:$D$32,Tidshorisont)
Name Diagram_SamNetto: Resultatunderlag!$G$8:INDEX(Resultatunderlag!$G$8:$G$32,Tidshorisont)
Name Namn_på_förändringen: Start!$B$4
Name Slicer_Bedömning: #N/A
Name Slicer_Bedömning1: #N/A
Name Slicer_Intressent: #N/A
Name Slicer_Intressent1: #N/A
Name Slicer_Intressent2: #N/A
Name Slicer_Intressent3: #N/A
Name Slicer_Intressent4: #N/A
Name Slicer_Intressent5: #N/A
Name Slicer_Intressent6: #N/A
Name Slicer_Intressent7: #N/A
Name Slicer_Kategori: #N/A
Name Slicer_Kategori1: #N/A
Name Slicer_Kategori2: #N/A
Name Slicer_Kategori3: #N/A
Name Slicer_Kategori4: #N/A
Name Slicer_Kategori5: #N/A
Name Startar: Start!$B$7

Sheet Start
B1: Start | C1: =IF(Namn_på_förändringen<>0,Namn_på_förändringen,"") | P1: Excelmall version 7.1
B3: Namn på förändringen
B6: Vilket år vill ni räkna från?
B9: Perspektiv

Sheet Värde nyttor
C1: Värde - nyttor | D1: =IF(Namn_på_förändringen<>0,Namn_på_förändringen,"")
C3: Faktorer som används i flera beräkningar | D3: Troligt | E3: Lägst | F3: Högst | G3: Källa
B12: N01 | D12: Namn
D13: Perspektiv | E13: {=IFERROR(INDEX(_xlfn.ANCHORARRAY(#REF!),#REF!,1),"")}
D14: Kategori
C16: Faktor | D16: Troligt | E16: Lägst | F16: Högst | G16: Källa
C23: Årligt värde (kr) → | I23: N01 | J23: =Startar+COLUMNS($J:J)-1 -> 0 | K23: =Startar+COLUMNS($J:K)-1 -> 1 | L23: =Startar+COLUMNS($J:L)-1 -> 2 | M23: =Startar+COLUMNS($J:M)-1 -> 3 | N23: =Startar+COLUMNS($J:N)-1 -> 4 | O23: =Startar+COLUMNS($J:O)-1 -> 5 | P23: =Startar+COLUMNS($J:P)-1 -> 6 | Q23: =Startar+COLUMNS($J:Q)-1 -> 7 | R23: =Startar+COLUMNS($J:R)-1 -> 8 | S23: =Startar+COLUMNS($J:S)-1 -> 9 | T23: =Startar+COLUMNS($J:T)-1 -> 10 | U23: =Startar+COLUMNS($J:U)-1 -> 11 | V23: =Startar+COLUMNS($J:V)-1 -> 12 | W23: =Startar+COLUMNS($J:W)-1 -> 13 | X23: =Startar+COLUMNS($J:X)-1 -> 14 | Y23: =Startar+COLUMNS($J:Y)-1 -> 15 | Z23: =Startar+COLUMNS($J:Z)-1 -> 16 | AA23: =Startar+COLUMNS($J:AA)-1 -> 17 | AB23: =Startar+COLUMNS($J:AB)-1 -> 18 | AC23: =Startar+COLUMNS($J:AC)-1 -> 19 | AD23: =Startar+COLUMNS($J:AD)-1 -> 20 | AE23: =Startar+COLUMNS($J:AE)-1 -> 21 | AF23: =Startar+COLUMNS($J:AF)-1 -> 22 | AG23: =Startar+COLUMNS($J:AG)-1 -> 23 | AH23: =Startar+COLUMNS($J:AH)-1 -> 24
I24: Troligt | J24: =$D23*J27 -> 0 | K24: =$D23*K27 -> 0 | L24: =$D23*L27 -> 0 | M24: =$D23*M27 -> 0 | N24: =$D23*N27 -> 0 | O24: =$D23*O27 -> 0 | P24: =$D23*P27 -> 0 | Q24: =$D23*Q27 -> 0 | ... AH24: =$D23*AH27 -> 0
I25: Lägst | J25: =$E23*J27 -> 0 | K25: =$E23*K27 -> 0 | L25: =$E23*L27 -> 0 | M25: =$E23*M27 -> 0 | N25: =$E23*N27 -> 0 | O25: =$E23*O27 -> 0 | P25: =$E23*P27 -> 0 | Q25: =$E23*Q27 -> 0 | ... AH25: =$E23*AH27 -> 0
I26: Högst | J26: =$F23*J27 -> 0 | K26: =$F23*K27 -> 0 | L26: =$F23*L27 -> 0 | M26: =$F23*M27 -> 0 | N26: =$F23*N27 -> 0 | O26: =$F23*O27 -> 0 | P26: =$F23*P27 -> 0 | Q26: =$F23*Q27 -> 0 | ... AH26: =$F23*AH27 -> 0
I27: Faktor | J27: 1 | K27: 1 | L27: 1 | M27: 1 | N27: 1 | O27: 1 | P27: 1 | Q27: 1 | R27: 1 | S27: 1 | T27: 1 | U27: 1 | V27: 1 | W27: 1 | X27: 1 | Y27: 1 | Z27: 1 | AA27: 1 | AB27: 1 | AC27: 1 | AD27: 1 | AE27: 1 | AF27: 1 | AG27: 1 | AH27: 1
B31: N02 | D31: Namn
D32: Perspektiv | E32: {=IFERROR(INDEX(_xlfn.ANCHORARRAY(#REF!),#REF!,1),"")}
D33: Kategori
C35: Faktor | D35: Troligt | E35: Lägst | F35: Högst | G35: Källa
C42: Årligt värde (kr) → | I42: N02 | J42: =Startar+COLUMNS($J:J)-1 -> 0 | K42: =Startar+COLUMNS($J:K)-1 -> 1 | L42: =Startar+COLUMNS($J:L)-1 -> 2 | M42: =Startar+COLUMNS($J:M)-1 -> 3 | N42: =Startar+COLUMNS($J:N)-1 -> 4 | O42: =Startar+COLUMNS($J:O)-1 -> 5 | P42: =Startar+COLUMNS($J:P)-1 -> 6 | Q42: =Startar+COLUMNS($J:Q)-1 -> 7 | R42: =Startar+COLUMNS($J:R)-1 -> 8 | S42: =Startar+COLUMNS($J:S)-1 -> 9 | T42: =Startar+COLUMNS($J:T)-1 -> 10 | U42: =Startar+COLUMNS($J:U)-1 -> 11 | V42: =Startar+COLUMNS($J:V)-1 -> 12 | W42: =Startar+COLUMNS($J:W)-1 -> 13 | X42: =Startar+COLUMNS($J:X)-1 -> 14 | Y42: =Startar+COLUMNS($J:Y)-1 -> 15 | Z42: =Startar+COLUMNS($J:Z)-1 -> 16 | AA42: =Startar+COLUMNS($J:AA)-1 -> 17 | AB42: =Startar+COLUMNS($J:AB)-1 -> 18 | AC42: =Startar+COLUMNS($J:AC)-1 -> 19 | AD42: =Startar+COLUMNS($J:AD)-1 -> 20 | AE42: =Startar+COLUMNS($J:AE)-1 -> 21 | AF42: =Startar+COLUMNS($J:AF)-1 -> 22 | AG42: =Startar+COLUMNS($J:AG)-1 -> 23 | AH42: =Startar+COLUMNS($J:AH)-1 -> 24
I43: Troligt | J43: =$D42*J46 -> 0 | K43: =$D42*K46 -> 0 | L43: =$D42*L46 -> 0 | M43: =$D42*M46 -> 0 | N43: =$D42*N46 -> 0 | O43: =$D42*O46 -> 0 | P43: =$D42*P46 -> 0 | Q43: =$D42*Q46 -> 0 | ... AH43: =$D42*AH46 -> 0
I44: Lägst | J44: =$E42*J46 -> 0 | K44: =$E42*K46 -> 0 | L44: =$E42*L46 -> 0 | M44: =$E42*M46 -> 0 | N44: =$E42*N46 -> 0 | O44: =$E42*O46 -> 0 | P44: =$E42*P46 -> 0 | Q44: =$E42*Q46 -> 0 | ... AH44: =$E42*AH46 -> 0
I45: Högst | J45: =$F42*J46 -> 0 | K45: =$F42*K46 -> 0 | L45: =$F42*L46 -> 0 | M45: =$F42*M46 -> 0 | N45: =$F42*N46 -> 0 | O45: =$F42*O46 -> 0 | P45: =$F42*P46 -> 0 | Q45: =$F42*Q46 -> 0 | ... AH45: =$F42*AH46 -> 0
I46: Faktor | J46: 1 | K46: 1 | L46: 1 | M46: 1 | N46: 1 | O46: 1 | P46: 1 | Q46: 1 | R46: 1 | S46: 1 | T46: 1 | U46: 1 | V46: 1 | W46: 1 | X46: 1 | Y46: 1 | Z46: 1 | AA46: 1 | AB46: 1 | AC46: 1 | AD46: 1 | AE46: 1 | AF46: 1 | AG46: 1 | AH46: 1
B50: N03 | D50: Namn
D51: Perspektiv | E51: {=IFERROR(INDEX(_xlfn.ANCHORARRAY(#REF!),#REF!,1),"")}
D52: Kategori
C54: Faktor | D54: Troligt | E54: Lägst | F54: Högst | G54: Källa
C61: Årligt värde (kr) → | I61: N03 | J61: =Startar+COLUMNS($J:J)-1 -> 0 | K61: =Startar+COLUMNS($J:K)-1 -> 1 | L61: =Startar+COLUMNS($J:L)-1 -> 2 | M61: =Startar+COLUMNS($J:M)-1 -> 3 | N61: =Startar+COLUMNS($J:N)-1 -> 4 | O61: =Startar+COLUMNS($J:O)-1 -> 5 | P61: =Startar+COLUMNS($J:P)-1 -> 6 | Q61: =Startar+COLUMNS($J:Q)-1 -> 7 | R61: =Startar+COLUMNS($J:R)-1 -> 8 | S61: =Startar+COLUMNS($J:S)-1 -> 9 | T61: =Startar+COLUMNS($J:T)-1 -> 10 | U61: =Startar+COLUMNS($J:U)-1 -> 11 | V61: =Startar+COLUMNS($J:V)-1 -> 12 | W61: =Startar+COLUMNS($J:W)-1 -> 13 | X61: =Startar+COLUMNS($J:X)-1 -> 14 | Y61: =Startar+COLUMNS($J:Y)-1 -> 15 | Z61: =Startar+COLUMNS($J:Z)-1 -> 16 | AA61: =Startar+COLUMNS($J:AA)-1 -> 17 | AB61: =Startar+COLUMNS($J:AB)-1 -> 18 | AC61: =Startar+COLUMNS($J:AC)-1 -> 19 | AD61: =Startar+COLUMNS($J:AD)-1 -> 20 | AE61: =Startar+COLUMNS($J:AE)-1 -> 21 | AF61: =Startar+COLUMNS($J:AF)-1 -> 22 | AG61: =Startar+COLUMNS($J:AG)-1 -> 23 | AH61: =Startar+COLUMNS($J:AH)-1 -> 24
I62: Troligt | J62: =$D61*J65 -> 0 | K62: =$D61*K65 -> 0 | L62: =$D61*L65 -> 0 | M62: =$D61*M65 -> 0 | N62: =$D61*N65 -> 0 | O62: =$D61*O65 -> 0 | P62: =$D61*P65 -> 0 | Q62: =$D61*Q65 -> 0 | ... AH62: =$D61*AH65 -> 0
I63: Lägst | J63: =$E61*J65 -> 0 | K63: =$E61*K65 -> 0 | L63: =$E61*L65 -> 0 | M63: =$E61*M65 -> 0 | N63: =$E61*N65 -> 0 | O63: =$E61*O65 -> 0 | P63: =$E61*P65 -> 0 | Q63: =$E61*Q65 -> 0 | ... AH63: =$E61*AH65 -> 0
I64: Högst | J64: =$F61*J65 -> 0 | K64: =$F61*K65 -> 0 | L64: =$F61*L65 -> 0 | M64: =$F61*M65 -> 0 | N64: =$F61*N65 -> 0 | O64: =$F61*O65 -> 0 | P64: =$F61*P65 -> 0 | Q64: =$F61*Q65 -> 0 | ... AH64: =$F61*AH65 -> 0
I65: Faktor | J65: 1 | K65: 1 | L65: 1 | M65: 1 | N65: 1 | O65: 1 | P65: 1 | Q65: 1 | R65: 1 | S65: 1 | T65: 1 | U65: 1 | V65: 1 | W65: 1 | X65: 1 | Y65: 1 | Z65: 1 | AA65: 1 | AB65: 1 | AC65: 1 | AD65: 1 | AE65: 1 | AF65: 1 | AG65: 1 | AH65: 1
B69: N04 | D69: Namn
D70: Perspektiv | E70: {=IFERROR(INDEX(_xlfn.ANCHORARRAY(#REF!),#REF!,1),"")}
D71: Kategori
C73: Faktor | D73: Troligt | E73: Lägst | F73: Högst | G73: Källa
C80: Årligt värde (kr) → | I80: N04 | J80: =Startar+COLUMNS($J:J)-1 -> 0 | K80: =Startar+COLUMNS($J:K)-1 -> 1 | L80: =Startar+COLUMNS($J:L)-1 -> 2 | M80: =Startar+COLUMNS($J:M)-1 -> 3 | N80: =Startar+COLUMNS($J:N)-1 -> 4 | O80: =Startar+COLUMNS($J:O)-1 -> 5 | P80: =Startar+COLUMNS($J:P)-1 -> 6 | Q80: =Startar+COLUMNS($J:Q)-1 -> 7 | R80: =Startar+COLUMNS($J:R)-1 -> 8 | S80: =Startar+COLUMNS($J:S)-1 -> 9 | T80: =Startar+COLUMNS($J:T)-1 -> 10 | U80: =Startar+COLUMNS($J:U)-1 -> 11 | V80: =Startar+COLUMNS($J:V)-1 -> 12 | W80: =Startar+COLUMNS($J:W)-1 -> 13 | X80: =Startar+COLUMNS($J:X)-1 -> 14 | Y80: =Startar+COLUMNS($J:Y)-1 -> 15 | Z80: =Startar+COLUMNS($J:Z)-1 -> 16 | AA80: =Startar+COLUMNS($J:AA)-1 -> 17 | AB80: =Startar+COLUMNS($J:AB)-1 -> 18 | AC80: =Startar+COLUMNS($J:AC)-1 -> 19 | AD80: =Startar+COLUMNS($J:AD)-1 -> 20 | AE80: =Startar+COLUMNS($J:AE)-1 -> 21 | AF80: =Startar+COLUMNS($J:AF)-1 -> 22 | AG80: =Startar+COLUMNS($J:AG)-1 -> 23 | AH80: =Startar+COLUMNS($J:AH)-1 -> 24
I81: Troligt | J81: =$D80*J84 -> 0 | K81: =$D80*K84 -> 0 | L81: =$D80*L84 -> 0 | M81: =$D80*M84 -> 0 | N81: =$D80*N84 -> 0 | O81: =$D80*O84 -> 0 | P81: =$D80*P84 -> 0 | Q81: =$D80*Q84 -> 0 | ... AH81: =$D80*AH84 -> 0
I82: Lägst | J82: =$E80*J84 -> 0 | K82: =$E80*K84 -> 0 | L82: =$E80*L84 -> 0 | M82: =$E80*M84 -> 0 | N82: =$E80*N84 -> 0 | O82: =$E80*O84 -> 0 | P82: =$E80*P84 -> 0 | Q82: =$E80*Q84 -> 0 | ... AH82: =$E80*AH84 -> 0
I83: Högst | J83: =$F80*J84 -> 0 | K83: =$F80*K84 -> 0 | L83: =$F80*L84 -> 0 | M83: =$F80*M84 -> 0 | N83: =$F80*N84 -> 0 | O83: =$F80*O84 -> 0 | P83: =$F80*P84 -> 0 | Q83: =$F80*Q84 -> 0 | ... AH83: =$F80*AH84 -> 0
I84: Faktor | J84: 1 | K84: 1 | L84: 1 | M84: 1 | N84: 1 | O84: 1 | P84: 1 | Q84: 1 | R84: 1 | S84: 1 | T84: 1 | U84: 1 | V84: 1 | W84: 1 | X84: 1 | Y84: 1 | Z84: 1 | AA84: 1 | AB84: 1 | AC84: 1 | AD84: 1 | AE84: 1 | AF84: 1 | AG84: 1 | AH84: 1
B88: N05 | D88: Namn
D89: Perspektiv | E89: {=IFERROR(INDEX(_xlfn.ANCHORARRAY(#REF!),#REF!,1),"")}
...

Sheet Värde kostnader
C1: Värde - kostnader | D1: =IF(Namn_på_förändringen<>0,Namn_på_förändringen,"")
C3: Faktorer som används i flera beräkningar | D3: Troligt | E3: Lägst | F3: Högst | G3: Källa
B12: K01 | D12: Namn
D13: Perspektiv | E13: {=IFERROR(INDEX(_xlfn.ANCHORARRAY(#REF!),#REF!,1),"")}
D14: Kategori
C16: Faktor | D16: Troligt | E16: Lägst | F16: Högst | G16: Källa
C23: Årligt värde (kr) → | I23: K01 | J23: =Startar+COLUMNS($J:J)-1 -> 0 | K23: =Startar+COLUMNS($J:K)-1 -> 1 | L23: =Startar+COLUMNS($J:L)-1 -> 2 | M23: =Startar+COLUMNS($J:M)-1 -> 3 | N23: =Startar+COLUMNS($J:N)-1 -> 4 | O23: =Startar+COLUMNS($J:O)-1 -> 5 | P23: =Startar+COLUMNS($J:P)-1 -> 6 | Q23: =Startar+COLUMNS($J:Q)-1 -> 7 | R23: =Startar+COLUMNS($J:R)-1 -> 8 | S23: =Startar+COLUMNS($J:S)-1 -> 9 | T23: =Startar+COLUMNS($J:T)-1 -> 10 | U23: =Startar+COLUMNS($J:U)-1 -> 11 | V23: =Startar+COLUMNS($J:V)-1 -> 12 | W23: =Startar+COLUMNS($J:W)-1 -> 13 | X23: =Startar+COLUMNS($J:X)-1 -> 14 | Y23: =Startar+COLUMNS($J:Y)-1 -> 15 | Z23: =Startar+COLUMNS($J:Z)-1 -> 16 | AA23: =Startar+COLUMNS($J:AA)-1 -> 17 | AB23: =Startar+COLUMNS($J:AB)-1 -> 18 | AC23: =Startar+COLUMNS($J:AC)-1 -> 19 | AD23: =Startar+COLUMNS($J:AD)-1 -> 20 | AE23: =Startar+COLUMNS($J:AE)-1 -> 21 | AF23: =Startar+COLUMNS($J:AF)-1 -> 22 | AG23: =Startar+COLUMNS($J:AG)-1 -> 23 | AH23: =Startar+COLUMNS($J:AH)-1 -> 24
I24: Troligt | J24: =$D23*J27 -> 0 | K24: =$D23*K27 -> 0 | L24: =$D23*L27 -> 0 | M24: =$D23*M27 -> 0 | N24: =$D23*N27 -> 0 | O24: =$D23*O27 -> 0 | P24: =$D23*P27 -> 0 | Q24: =$D23*Q27 -> 0 | ... AH24: =$D23*AH27 -> 0
I25: Lägst | J25: =$E23*J27 -> 0 | K25: =$E23*K27 -> 0 | L25: =$E23*L27 -> 0 | M25: =$E23*M27 -> 0 | N25: =$E23*N27 -> 0 | O25: =$E23*O27 -> 0 | P25: =$E23*P27 -> 0 | Q25: =$E23*Q27 -> 0 | ... AH25: =$E23*AH27 -> 0
I26: Högst | J26: =$F23*J27 -> 0 | K26: =$F23*K27 -> 0 | L26: =$F23*L27 -> 0 | M26: =$F23*M27 -> 0 | N26: =$F23*N27 -> 0 | O26: =$F23*O27 -> 0 | P26: =$F23*P27 -> 0 | Q26: =$F23*Q27 -> 0 | ... AH26: =$F23*AH27 -> 0
I27: Faktor | J27: 1 | K27: 1 | L27: 1 | M27: 1 | N27: 1 | O27: 1 | P27: 1 | Q27: 1 | R27: 1 | S27: 1 | T27: 1 | U27: 1 | V27: 1 | W27: 1 | X27: 1 | Y27: 1 | Z27: 1 | AA27: 1 | AB27: 1 | AC27: 1 | AD27: 1 | AE27: 1 | AF27: 1 | AG27: 1 | AH27: 1
B31: K02 | D31: Namn
D32: Perspektiv | E32: {=IFERROR(INDEX(_xlfn.ANCHORARRAY(#REF!),#REF!,1),"")}
D33: Kategori
C35: Faktor | D35: Troligt | E35: Lägst | F35: Högst | G35: Källa
C42: Årligt värde (kr) → | I42: K02 | J42: =Startar+COLUMNS($J:J)-1 -> 0 | K42: =Startar+COLUMNS($J:K)-1 -> 1 | L42: =Startar+COLUMNS($J:L)-1 -> 2 | M42: =Startar+COLUMNS($J:M)-1 -> 3 | N42: =Startar+COLUMNS($J:N)-1 -> 4 | O42: =Startar+COLUMNS($J:O)-1 -> 5 | P42: =Startar+COLUMNS($J:P)-1 -> 6 | Q42: =Startar+COLUMNS($J:Q)-1 -> 7 | R42: =Startar+COLUMNS($J:R)-1 -> 8 | S42: =Startar+COLUMNS($J:S)-1 -> 9 | T42: =Startar+COLUMNS($J:T)-1 -> 10 | U42: =Startar+COLUMNS($J:U)-1 -> 11 | V42: =Startar+COLUMNS($J:V)-1 -> 12 | W42: =Startar+COLUMNS($J:W)-1 -> 13 | X42: =Startar+COLUMNS($J:X)-1 -> 14 | Y42: =Startar+COLUMNS($J:Y)-1 -> 15 | Z42: =Startar+COLUMNS($J:Z)-1 -> 16 | AA42: =Startar+COLUMNS($J:AA)-1 -> 17 | AB42: =Startar+COLUMNS($J:AB)-1 -> 18 | AC42: =Startar+COLUMNS($J:AC)-1 -> 19 | AD42: =Startar+COLUMNS($J:AD)-1 -> 20 | AE42: =Startar+COLUMNS($J:AE)-1 -> 21 | AF42: =Startar+COLUMNS($J:AF)-1 -> 22 | AG42: =Startar+COLUMNS($J:AG)-1 -> 23 | AH42: =Startar+COLUMNS($J:AH)-1 -> 24
I43: Troligt | J43: =$D42*J46 -> 0 | K43: =$D42*K46 -> 0 | L43: =$D42*L46 -> 0 | M43: =$D42*M46 -> 0 | N43: =$D42*N46 -> 0 | O43: =$D42*O46 -> 0 | P43: =$D42*P46 -> 0 | Q43: =$D42*Q46 -> 0 | ... AH43: =$D42*AH46 -> 0
I44: Lägst | J44: =$E42*J46 -> 0 | K44: =$E42*K46 -> 0 | L44: =$E42*L46 -> 0 | M44: =$E42*M46 -> 0 | N44: =$E42*N46 -> 0 | O44: =$E42*O46 -> 0 | P44: =$E42*P46 -> 0 | Q44: =$E42*Q46 -> 0 | ... AH44: =$E42*AH46 -> 0
I45: Högst | J45: =$F42*J46 -> 0 | K45: =$F42*K46 -> 0 | L45: =$F42*L46 -> 0 | M45: =$F42*M46 -> 0 | N45: =$F42*N46 -> 0 | O45: =$F42*O46 -> 0 | P45: =$F42*P46 -> 0 | Q45: =$F42*Q46 -> 0 | ... AH45: =$F42*AH46 -> 0
I46: Faktor | J46: 1 | K46: 1 | L46: 1 | M46: 1 | N46: 1 | O46: 1 | P46: 1 | Q46: 1 | R46: 1 | S46: 1 | T46: 1 | U46: 1 | V46: 1 | W46: 1 | X46: 1 | Y46: 1 | Z46: 1 | AA46: 1 | AB46: 1 | AC46: 1 | AD46: 1 | AE46: 1 | AF46: 1 | AG46: 1 | AH46: 1
B50: K03 | D50: Namn
D51: Perspektiv | E51: {=IFERROR(INDEX(_xlfn.ANCHORARRAY(#REF!),#REF!,1),"")}
D52: Kategori
C54: Faktor | D54: Troligt | E54: Lägst | F54: Högst | G54: Källa
C61: Årligt värde (kr) → | I61: K03 | J61: =Startar+COLUMNS($J:J)-1 -> 0 | K61: =Startar+COLUMNS($J:K)-1 -> 1 | L61: =Startar+COLUMNS($J:L)-1 -> 2 | M61: =Startar+COLUMNS($J:M)-1 -> 3 | N61: =Startar+COLUMNS($J:N)-1 -> 4 | O61: =Startar+COLUMNS($J:O)-1 -> 5 | P61: =Startar+COLUMNS($J:P)-1 -> 6 | Q61: =Startar+COLUMNS($J:Q)-1 -> 7 | R61: =Startar+COLUMNS($J:R)-1 -> 8 | S61: =Startar+COLUMNS($J:S)-1 -> 9 | T61: =Startar+COLUMNS($J:T)-1 -> 10 | U61: =Startar+COLUMNS($J:U)-1 -> 11 | V61: =Startar+COLUMNS($J:V)-1 -> 12 | W61: =Startar+COLUMNS($J:W)-1 -> 13 | X61: =Startar+COLUMNS($J:X)-1 -> 14 | Y61: =Startar+COLUMNS($J:Y)-1 -> 15 | Z61: =Startar+COLUMNS($J:Z)-1 -> 16 | AA61: =Startar+COLUMNS($J:AA)-1 -> 17 | AB61: =Startar+COLUMNS($J:AB)-1 -> 18 | AC61: =Startar+COLUMNS($J:AC)-1 -> 19 | AD61: =Startar+COLUMNS($J:AD)-1 -> 20 | AE61: =Startar+COLUMNS($J:AE)-1 -> 21 | AF61: =Startar+COLUMNS($J:AF)-1 -> 22 | AG61: =Startar+COLUMNS($J:AG)-1 -> 23 | AH61: =Startar+COLUMNS($J:AH)-1 -> 24
I62: Troligt | J62: =$D61*J65 -> 0 | K62: =$D61*K65 -> 0 | L62: =$D61*L65 -> 0 | M62: =$D61*M65 -> 0 | N62: =$D61*N65 -> 0 | O62: =$D61*O65 -> 0 | P62: =$D61*P65 -> 0 | Q62: =$D61*Q65 -> 0 | ... AH62: =$D61*AH65 -> 0
I63: Lägst | J63: =$E61*J65 -> 0 | K63: =$E61*K65 -> 0 | L63: =$E61*L65 -> 0 | M63: =$E61*M65 -> 0 | N63: =$E61*N65 -> 0 | O63: =$E61*O65 -> 0 | P63: =$E61*P65 -> 0 | Q63: =$E61*Q65 -> 0 | ... AH63: =$E61*AH65 -> 0
I64: Högst | J64: =$F61*J65 -> 0 | K64: =$F61*K65 -> 0 | L64: =$F61*L65 -> 0 | M64: =$F61*M65 -> 0 | N64: =$F61*N65 -> 0 | O64: =$F61*O65 -> 0 | P64: =$F61*P65 -> 0 | Q64: =$F61*Q65 -> 0 | ... AH64: =$F61*AH65 -> 0
I65: Faktor | J65: 1 | K65: 1 | L65: 1 | M65: 1 | N65: 1 | O65: 1 | P65: 1 | Q65: 1 | R65: 1 | S65: 1 | T65: 1 | U65: 1 | V65: 1 | W65: 1 | X65: 1 | Y65: 1 | Z65: 1 | AA65: 1 | AB65: 1 | AC65: 1 | AD65: 1 | AE65: 1 | AF65: 1 | AG65: 1 | AH65: 1
B69: K04 | D69: Namn
D70: Perspektiv | E70: {=IFERROR(INDEX(_xlfn.ANCHORARRAY(#REF!),#REF!,1),"")}
D71: Kategori
C73: Faktor | D73: Troligt | E73: Lägst | F73: Högst | G73: Källa
C80: Årligt värde (kr) → | I80: K04 | J80: =Startar+COLUMNS($J:J)-1 -> 0 | K80: =Startar+COLUMNS($J:K)-1 -> 1 | L80: =Startar+COLUMNS($J:L)-1 -> 2 | M80: =Startar+COLUMNS($J:M)-1 -> 3 | N80: =Startar+COLUMNS($J:N)-1 -> 4 | O80: =Startar+COLUMNS($J:O)-1 -> 5 | P80: =Startar+COLUMNS($J:P)-1 -> 6 | Q80: =Startar+COLUMNS($J:Q)-1 -> 7 | R80: =Startar+COLUMNS($J:R)-1 -> 8 | S80: =Startar+COLUMNS($J:S)-1 -> 9 | T80: =Startar+COLUMNS($J:T)-1 -> 10 | U80: =Startar+COLUMNS($J:U)-1 -> 11 | V80: =Startar+COLUMNS($J:V)-1 -> 12 | W80: =Startar+COLUMNS($J:W)-1 -> 13 | X80: =Startar+COLUMNS($J:X)-1 -> 14 | Y80: =Startar+COLUMNS($J:Y)-1 -> 15 | Z80: =Startar+COLUMNS($J:Z)-1 -> 16 | AA80: =Startar+COLUMNS($J:AA)-1 -> 17 | AB80: =Startar+COLUMNS($J:AB)-1 -> 18 | AC80: =Startar+COLUMNS($J:AC)-1 -> 19 | AD80: =Startar+COLUMNS($J:AD)-1 -> 20 | AE80: =Startar+COLUMNS($J:AE)-1 -> 21 | AF80: =Startar+COLUMNS($J:AF)-1 -> 22 | AG80: =Startar+COLUMNS($J:AG)-1 -> 23 | AH80: =Startar+COLUMNS($J:AH)-1 -> 24
I81: Troligt | J81: =$D80*J84 -> 0 | K81: =$D80*K84 -> 0 | L81: =$D80*L84 -> 0 | M81: =$D80*M84 -> 0 | N81: =$D80*N84 -> 0 | O81: =$D80*O84 -> 0 | P81: =$D80*P84 -> 0 | Q81: =$D80*Q84 -> 0 | ... AH81: =$D80*AH84 -> 0
I82: Lägst | J82: =$E80*J84 -> 0 | K82: =$E80*K84 -> 0 | L82: =$E80*L84 -> 0 | M82: =$E80*M84 -> 0 | N82: =$E80*N84 -> 0 | O82: =$E80*O84 -> 0 | P82: =$E80*P84 -> 0 | Q82: =$E80*Q84 -> 0 | ... AH82: =$E80*AH84 -> 0
I83: Högst | J83: =$F80*J84 -> 0 | K83: =$F80*K84 -> 0 | L83: =$F80*L84 -> 0 | M83: =$F80*M84 -> 0 | N83: =$F80*N84 -> 0 | O83: =$F80*O84 -> 0 | P83: =$F80*P84 -> 0 | Q83: =$F80*Q84 -> 0 | ... AH83: =$F80*AH84 -> 0
I84: Faktor | J84: 1 | K84: 1 | L84: 1 | M84: 1 | N84: 1 | O84: 1 | P84: 1 | Q84: 1 | R84: 1 | S84: 1 | T84: 1 | U84: 1 | V84: 1 | W84: 1 | X84: 1 | Y84: 1 | Z84: 1 | AA84: 1 | AB84: 1 | AC84: 1 | AD84: 1 | AE84: 1 | AF84: 1 | AG84: 1 | AH84: 1
B88: K05 | D88: Namn
D89: Perspektiv | E89: {=IFERROR(INDEX(_xlfn.ANCHORARRAY(#REF!),#REF!,1),"")}
...

Sheet Ej värderade
C1: Ej värderade | D1: =IF(Namn_på_förändringen<>0,Namn_på_förändringen,"")
C3: Nytta | D3: Perspektiv | E3: Kategori | F3: Uppskattad storlek | I3: Kostnad | J3: Perspektiv | K3: Kategori | L3: Uppskattad storlek

Sheet Resultat
C2: Resultat | D2: =IF(Namn_på_förändringen<>0,Namn_på_förändringen,"") | N2: Diskonteringsränta | O2: 0.03
C5: Överblick: nyttor och kostnader som värderats i pengar | K5: Filtrera denna sektion
C16: Tabell: sammanfattning
C17: ="Sammanlagd nettonytta efter " &Input!B11&" (kr)" -> Sammanlagd nettonytta efter 25 år (kr) | D17: =Resultatunderlag!C37 -> 0
C18: ="Nettonytta per satsad krona efter "&Input!B11 -> Nettonytta per satsad krona efter 25 år | D18: =Resultatunderlag!C38 -> 0
C19: Året som de sammanlagda nyttorna överstiger kostnaderna | D19: {=IFERROR(INDEX(Resultatunderlag!B8:B32, MATCH(TRUE, Resultatunderlag!G8:G32>0, 0)), "aldrig")} -> aldrig
C20: Nytta - finansiell | D20: =IFERROR(GETPIVOTDATA("[Measures].[Sum of Summa 3]",Resultatunderlag!$B$73,"[Varderade_nyttor].[Kategori]","[Varderade_nyttor].[Kategori].&[Finansiell 💰]"),0) -> 0
C21: Nytta - omfördelning | D21: =IFERROR(GETPIVOTDATA("[Measures].[Sum of Summa 3]",Resultatunderlag!$B$73,"[Varderade_nyttor].[Kategori]","[Varderade_nyttor].[Kategori].&[Omfördelning ↺]"),0) -> 0
C22: Kostnad - finansiell | D22: =IFERROR(GETPIVOTDATA("[Measures].[Sum of Summa 4]",Resultatunderlag!$E$73,"[Varderade_kostnader].[Kategori]","[Varderade_kostnader].[Kategori].&[Finansiell 💰]"),0) -> 0
C23: Kostnad - omfördelning | D23: =IFERROR(GETPIVOTDATA("[Measures].[Sum of Summa 4]",Resultatunderlag!$E$73,"[Varderade_kostnader].[Kategori]","[Varderade_kostnader].[Kategori].&[Omfördelning ↺]"),0) -> 0
C24: Nyttor som inte värderats i pengar | D24: =Resultatunderlag!C94 -> 0 / 0
C28: Nyttor och kostnader som inte värderats i pengar | K28: Filtrera denna sektion
C39: Uppskattad storlek på nyttor som inte värderats i pengar | G39: Uppskattad storlek på kostnader som inte värderats i pengar
C64: Osäkerhet för nyttor och kostnader som värderats i pengar | K64: Filtrera denna sektion
G66: ="Tabell: Nettonytta per satsad krona efter " &Input!B11& " (kr)" -> Tabell: Nettonytta per satsad krona efter 25 år (kr)
G67: =Resultatunderlag!D114 -> (Lägst nytta - lägst kostnad) / Lägst kostnad | H67: =IFERROR(Resultatunderlag!E114,"")
G68: =Resultatunderlag!D115 -> (Trolig nytta - trolig kostnad) / Trolig kostnad | H68: =IFERROR(Resultatunderlag!E115,"")
G69: =Resultatunderlag!D116 -> (Högst nytta - högst kostnad) / Högst kostnad | H69: =IFERROR(Resultatunderlag!E116,"")
C78: Fördjupning: nyttor och kostnader som värderats i pengar | K78: Filtrera denna sektion
C81: Nyttor som värderats i pengar, per kategori | D81: Andel av de värderade nyttorna | E81: Värde i kr | G81: Kostnader som inte värderats i pengar, per kategori | H81: Andel av de värderade nyttorna | I81: Värde i kr
C82: Finansiell 💰
C83: aasd | D83: 1 | E83: 53806626
C85: Summa | D85: 1 | E85: 53806626
C106: Nyttor som värderats i pengar per perspektiv | D106: Andel av de värderade nyttorna | E106: Värde i kr | G106: Kostnader som värderats i pengar per perspektiv | H106: Andel av de värderade kostnaderna | I106: Värde i kr
C107: af | D107: 1 | E107: 53806626
C108: Summa | D108: 1 | E108: 53806626
C122: Fördjupning: beräkna omfördelning som timmar och årsarbetare
C124: Årsarbetstid i snitt (timmar) | D124: 1700
C126: Nytta | D126: ="Totalt värde efter " & Input!$B$11 &" (kr)" -> Totalt värde efter 25 år (kr) | E126: Timkostnad (kr) | F126: ="Frigjorda timmar efter " &Input!$B$11 -> Frigjorda timmar efter 25 år | G126: ="Frigjorda årsarbetare totalt under " & Input!$B$11 -> Frigjorda årsarbetare totalt under 25 år
C127: {=_xlfn._xlws.FILTER(_xlfn.HSTACK(AN!D2:D16,AN!AI2:AI16),AN!F2:F16="Omfördelning ↺","")} | F127: =IFERROR(D127/E127,"") | G127: =IFERROR(F127/$D$124,"")
F128: =IFERROR(D128/E128,"") | G128: =IFERROR(F128/$D$124,"")
F129: =IFERROR(D129/E129,"") | G129: =IFERROR(F129/$D$124,"")
F130: =IFERROR(D130/E130,"") | G130: =IFERROR(F130/$D$124,"")
F131: =IFERROR(D131/E131,"") | G131: =IFERROR(F131/$D$124,"")
F132: =IFERROR(D132/E132,"") | G132: =IFERROR(F132/$D$124,"")
F133: =IFERROR(D133/E133,"") | G133: =IFERROR(F133/$D$124,"")
F134: =IFERROR(D134/E134,"") | G134: =IFERROR(F134/$D$124,"")
F135: =IFERROR(D135/E135,"") | G135: =IFERROR(F135/$D$124,"")
F136: =IFERROR(D136/E136,"") | G136: =IFERROR(F136/$D$124,"")
F137: =IFERROR(D137/E137,"") | G137: =IFERROR(F137/$D$124,"")
...

Sheet Planera uppföljning
B1: Planera uppföljning | C1: =IF(Namn_på_förändringen<>0,Namn_på_förändringen,"")
B3: Användning
B5: Indikator på användning | C5: Källa | D5: Kommentar
B11: Nyttor
B13: Nytta | C13: Kategori | D13: ="Värdering i pengar efter " &Input!B11 &" (kr)" -> Värdering i pengar efter 25 år (kr) | E13: Uppskattad storlek | F13: Indikator | G13: Källa | H13: Kommentar
B14: {=IFERROR(_xlfn._xlws.FILTER(_xlfn.HSTACK(Tabell_AN[Nytta],Tabell_AN[Kategori],IF(Tabell_AN[Summa]<>0,Tabell_AN[Summa],""),IF(Tabell_AN[Bedömning]<>"",Tabell_AN[Bedömning],"")),(Tabell_AN[NID]<>"")*(Tabell_AN[Nytta]<>0)),"")}
B33: Kostnader
B35: Kostnad | C35: Kategori | D35: ="Värdering i pengar efter " &Input!B11 &" (kr)" -> Värdering i pengar efter 25 år (kr) | E35: Uppskattad storlek | F35: Indikator | G35: Källa | H35: Kommentar
B36: {=IFERROR(_xlfn._xlws.FILTER(_xlfn.HSTACK(Tabell_AK[Kostnad],Tabell_AK[Kategori],IF(Tabell_AK[Summa]<>0,Tabell_AK[Summa],""),IF(Tabell_AK[Bedömning]<>"",Tabell_AK[Bedömning],"")),(Tabell_AK[KID]<>"")*(Tabell_AK[Kostnad]<>0)),"")}

Sheet Resultatunderlag
B1: Resultatunderlag | G1: Gula fält används i resultatvyn
B4: Underlag för diagrammet i överblick
B6: Underlag för diagrammet i överblick
B7: År | C7: Finansiell nytta | D7: Omfördelningsnytta | E7: Finansiell kostnad | F7: Omfördelningskostnad | G7: Sammanlagd nettonytta
B8: =Startar -> 0 | C8: =IFERROR(GETPIVOTDATA("[Measures].[Sum of Troligt år "&($B8-$B$8+1)&" 3]",$B$40,"[Varderade_nyttor].[Kategori]","[Varderade_nyttor].[Kategori].&[Finansiell 💰]"),0) -> 0 | D8: =IFERROR(GETPIVOTDATA("[Measures].[Sum of Troligt år "&($B8-$B$8+1)&" 3]",$B$40,"[Varderade_nyttor].[Kategori]","[Varderade_nyttor].[Kategori].&[Omfördelning ↺]"),0) -> 0 | E8: =IFERROR(GETPIVOTDATA("[Measures].[Sum of Troligt år "&($B8-$B$8+1)&" 4]",$F$40,"[Varderade_kostnader].[Kategori]","[Varderade_kostnader].[Kategori].&[Finansiell 💰]"),0) -> 0 | F8: =IFERROR(GETPIVOTDATA("[Measures].[Sum of Troligt år "&($B8-$B$8+1)&" 4]",$F$40,"[Varderade_kostnader].[Kategori]","[Varderade_kostnader].[Kategori].&[Omfördelning ↺]"),0) -> 0 | G8: =IF($B8="",NA(),SUM($C$8:C8)+SUM($D$8:D8)+SUM($E$8:E8)+SUM($F$8:F8)) -> 0
B9: =B8+1 -> 1 | C9: =IFERROR(GETPIVOTDATA("[Measures].[Sum of Troligt år "&($B9-$B$8+1)&" 3]",$B$40,"[Varderade_nyttor].[Kategori]","[Varderade_nyttor].[Kategori].&[Finansiell 💰]"),0) -> 0 | D9: =IFERROR(GETPIVOTDATA("[Measures].[Sum of Troligt år "&($B9-$B$8+1)&" 3]",$B$40,"[Varderade_nyttor].[Kategori]","[Varderade_nyttor].[Kategori].&[Omfördelning ↺]"),0) -> 0 | E9: =IFERROR(GETPIVOTDATA("[Measures].[Sum of Troligt år "&($B9-$B$8+1)&" 4]",$F$40,"[Varderade_kostnader].[Kategori]","[Varderade_kostnader].[Kategori].&[Finansiell 💰]"),0) -> 0 | F9: =IFERROR(GETPIVOTDATA("[Measures].[Sum of Troligt år "&($B9-$B$8+1)&" 4]",$F$40,"[Varderade_kostnader].[Kategori]","[Varderade_kostnader].[Kategori].&[Omfördelning ↺]"),0) -> 0 | G9: =IF($B9="",NA(),SUM($C$8:C9)+SUM($D$8:D9)+SUM($E$8:E9)+SUM($F$8:F9)) -> 0
B10: =B9+1 -> 2 | C10: =IFERROR(GETPIVOTDATA("[Measures].[Sum of Troligt år "&($B10-$B$8+1)&" 3]",$B$40,"[Varderade_nyttor].[Kategori]","[Varderade_nyttor].[Kategori].&[Finansiell 💰]"),0) -> 0 | D10: =IFERROR(GETPIVOTDATA("[Measures].[Sum of Troligt år "&($B10-$B$8+1)&" 3]",$B$40,"[Varderade_nyttor].[Kategori]","[Varderade_nyttor].[Kategori].&[Omfördelning ↺]"),0) -> 0 | E10: =IFERROR(GETPIVOTDATA("[Measures].[Sum of Troligt år "&($B10-$B$8+1)&" 4]",$F$40,"[Varderade_kostnader].[Kategori]","[Varderade_kostnader].[Kategori].&[Finansiell 💰]"),0) -> 0 | F10: =IFERROR(GETPIVOTDATA("[Measures].[Sum of Troligt år "&($B10-$B$8+1)&" 4]",$F$40,"[Varderade_kostnader].[Kategori]","[Varderade_kostnader].[Kategori].&[Omfördelning ↺]"),0) -> 0 | G10: =IF($B10="",NA(),SUM($C$8:C10)+SUM($D$8:D10)+SUM($E$8:E10)+SUM($F$8:F10)) -> 0
B11: =B10+1 -> 3 | C11: =IFERROR(GETPIVOTDATA("[Measures].[Sum of Troligt år "&($B11-$B$8+1)&" 3]",$B$40,"[Varderade_nyttor].[Kategori]","[Varderade_nyttor].[Kategori].&[Finansiell 💰]"),0) -> 0 | D11: =IFERROR(GETPIVOTDATA("[Measures].[Sum of Troligt år "&($B11-$B$8+1)&" 3]",$B$40,"[Varderade_nyttor].[Kategori]","[Varderade_nyttor].[Kategori].&[Omfördelning ↺]"),0) -> 0 | E11: =IFERROR(GETPIVOTDATA("[Measures].[Sum of Troligt år "&($B11-$B$8+1)&" 4]",$F$40,"[Varderade_kostnader].[Kategori]","[Varderade_kostnader].[Kategori].&[Finansiell 💰]"),0) -> 0 | F11: =IFERROR(GETPIVOTDATA("[Measures].[Sum of Troligt år "&($B11-$B$8+1)&" 4]",$F$40,"[Varderade_kostnader].[Kategori]","[Varderade_kostnader].[Kategori].&[Omfördelning ↺]"),0) -> 0 | G11: =IF($B11="",NA(),SUM($C$8:C11)+SUM($D$8:D11)+SUM($E$8:E11)+SUM($F$8:F11)) -> 0
B12: =B11+1 -> 4 | C12: =IFERROR(GETPIVOTDATA("[Measures].[Sum of Troligt år "&($B12-$B$8+1)&" 3]",$B$40,"[Varderade_nyttor].[Kategori]","[Varderade_nyttor].[Kategori].&[Finansiell 💰]"),0) -> 0 | D12: =IFERROR(GETPIVOTDATA("[Measures].[Sum of Troligt år "&($B12-$B$8+1)&" 3]",$B$40,"[Varderade_nyttor].[Kategori]","[Varderade_nyttor].[Kategori].&[Omfördelning ↺]"),0) -> 0 | E12: =IFERROR(GETPIVOTDATA("[Measures].[Sum of Troligt år "&($B12-$B$8+1)&" 4]",$F$40,"[Varderade_kostnader].[Kategori]","[Varderade_kostnader].[Kategori].&[Finansiell 💰]"),0) -> 0 | F12: =IFERROR(GETPIVOTDATA("[Measures].[Sum of Troligt år "&($B12-$B$8+1)&" 4]",$F$40,"[Varderade_kostnader].[Kategori]","[Varderade_kostnader].[Kategori].&[Omfördelning ↺]"),0) -> 0 | G12: =IF($B12="",NA(),SUM($C$8:C12)+SUM($D$8:D12)+SUM($E$8:E12)+SUM($F$8:F12)) -> 0
B13: =B12+1 -> 5 | C13: =IFERROR(GETPIVOTDATA("[Measures].[Sum of Troligt år "&($B13-$B$8+1)&" 3]",$B$40,"[Varderade_nyttor].[Kategori]","[Varderade_nyttor].[Kategori].&[Finansiell 💰]"),0) -> 0 | D13: =IFERROR(GETPIVOTDATA("[Measures].[Sum of Troligt år "&($B13-$B$8+1)&" 3]",$B$40,"[Varderade_nyttor].[Kategori]","[Varderade_nyttor].[Kategori].&[Omfördelning ↺]"),0) -> 0 | E13: =IFERROR(GETPIVOTDATA("[Measures].[Sum of Troligt år "&($B13-$B$8+1)&" 4]",$F$40,"[Varderade_kostnader].[Kategori]","[Varderade_kostnader].[Kategori].&[Finansiell 💰]"),0) -> 0 | F13: =IFERROR(GETPIVOTDATA("[Measures].[Sum of Troligt år "&($B13-$B$8+1)&" 4]",$F$40,"[Varderade_kostnader].[Kategori]","[Varderade_kostnader].[Kategori].&[Omfördelning ↺]"),0) -> 0 | G13: =IF($B13="",NA(),SUM($C$8:C13)+SUM($D$8:D13)+SUM($E$8:E13)+SUM($F$8:F13)) -> 0
B14: =B13+1 -> 6 | C14: =IFERROR(GETPIVOTDATA("[Measures].[Sum of Troligt år "&($B14-$B$8+1)&" 3]",$B$40,"[Varderade_nyttor].[Kategori]","[Varderade_nyttor].[Kategori].&[Finansiell 💰]"),0) -> 0 | D14: =IFERROR(GETPIVOTDATA("[Measures].[Sum of Troligt år "&($B14-$B$8+1)&" 3]",$B$40,"[Varderade_nyttor].[Kategori]","[Varderade_nyttor].[Kategori].&[Omfördelning ↺]"),0) -> 0 | E14: =IFERROR(GETPIVOTDATA("[Measures].[Sum of Troligt år "&($B14-$B$8+1)&" 4]",$F$40,"[Varderade_kostnader].[Kategori]","[Varderade_kostnader].[Kategori].&[Finansiell 💰]"),0) -> 0 | F14: =IFERROR(GETPIVOTDATA("[Measures].[Sum of Troligt år "&($B14-$B$8+1)&" 4]",$F$40,"[Varderade_kostnader].[Kategori]","[Varderade_kostnader].[Kategori].&[Omfördelning ↺]"),0) -> 0 | G14: =IF($B14="",NA(),SUM($C$8:C14)+SUM($D$8:D14)+SUM($E$8:E14)+SUM($F$8:F14)) -> 0
B15: =B14+1 -> 7 | C15: =IFERROR(GETPIVOTDATA("[Measures].[Sum of Troligt år "&($B15-$B$8+1)&" 3]",$B$40,"[Varderade_nyttor].[Kategori]","[Varderade_nyttor].[Kategori].&[Finansiell 💰]"),0) -> 0 | D15: =IFERROR(GETPIVOTDATA("[Measures].[Sum of Troligt år "&($B15-$B$8+1)&" 3]",$B$40,"[Varderade_nyttor].[Kategori]","[Varderade_nyttor].[Kategori].&[Omfördelning ↺]"),0) -> 0 | E15: =IFERROR(GETPIVOTDATA("[Measures].[Sum of Troligt år "&($B15-$B$8+1)&" 4]",$F$40,"[Varderade_kostnader].[Kategori]","[Varderade_kostnader].[Kategori].&[Finansiell 💰]"),0) -> 0 | F15: =IFERROR(GETPIVOTDATA("[Measures].[Sum of Troligt år "&($B15-$B$8+1)&" 4]",$F$40,"[Varderade_kostnader].[Kategori]","[Varderade_kostnader].[Kategori].&[Omfördelning ↺]"),0) -> 0 | G15: =IF($B15="",NA(),SUM($C$8:C15)+SUM($D$8:D15)+SUM($E$8:E15)+SUM($F$8:F15)) -> 0
B16: =B15+1 -> 8 | C16: =IFERROR(GETPIVOTDATA("[Measures].[Sum of Troligt år "&($B16-$B$8+1)&" 3]",$B$40,"[Varderade_nyttor].[Kategori]","[Varderade_nyttor].[Kategori].&[Finansiell 💰]"),0) -> 0 | D16: =IFERROR(GETPIVOTDATA("[Measures].[Sum of Troligt år "&($B16-$B$8+1)&" 3]",$B$40,"[Varderade_nyttor].[Kategori]","[Varderade_nyttor].[Kategori].&[Omfördelning ↺]"),0) -> 0 | E16: =IFERROR(GETPIVOTDATA("[Measures].[Sum of Troligt år "&($B16-$B$8+1)&" 4]",$F$40,"[Varderade_kostnader].[Kategori]","[Varderade_kostnader].[Kategori].&[Finansiell 💰]"),0) -> 0 | F16: =IFERROR(GETPIVOTDATA("[Measures].[Sum of Troligt år "&($B16-$B$8+1)&" 4]",$F$40,"[Varderade_kostnader].[Kategori]","[Varderade_kostnader].[Kategori].&[Omfördelning ↺]"),0) -> 0 | G16: =IF($B16="",NA(),SUM($C$8:C16)+SUM($D$8:D16)+SUM($E$8:E16)+SUM($F$8:F16)) -> 0
B17: =B16+1 -> 9 | C17: =IFERROR(GETPIVOTDATA("[Measures].[Sum of Troligt år "&($B17-$B$8+1)&" 3]",$B$40,"[Varderade_nyttor].[Kategori]","[Varderade_nyttor].[Kategori].&[Finansiell 💰]"),0) -> 0 | D17: =IFERROR(GETPIVOTDATA("[Measures].[Sum of Troligt år "&($B17-$B$8+1)&" 3]",$B$40,"[Varderade_nyttor].[Kategori]","[Varderade_nyttor].[Kategori].&[Omfördelning ↺]"),0) -> 0 | E17: =IFERROR(GETPIVOTDATA("[Measures].[Sum of Troligt år "&($B17-$B$8+1)&" 4]",$F$40,"[Varderade_kostnader].[Kategori]","[Varderade_kostnader].[Kategori].&[Finansiell 💰]"),0) -> 0 | F17: =IFERROR(GETPIVOTDATA("[Measures].[Sum of Troligt år "&($B17-$B$8+1)&" 4]",$F$40,"[Varderade_kostnader].[Kategori]","[Varderade_kostnader].[Kategori].&[Omfördelning ↺]"),0) -> 0 | G17: =IF($B17="",NA(),SUM($C$8:C17)+SUM($D$8:D17)+SUM($E$8:E17)+SUM($F$8:F17)) -> 0
B18: =B17+1 -> 10 | C18: =IFERROR(GETPIVOTDATA("[Measures].[Sum of Troligt år "&($B18-$B$8+1)&" 3]",$B$40,"[Varderade_nyttor].[Kategori]","[Varderade_nyttor].[Kategori].&[Finansiell 💰]"),0) -> 0 | D18: =IFERROR(GETPIVOTDATA("[Measures].[Sum of Troligt år "&($B18-$B$8+1)&" 3]",$B$40,"[Varderade_nyttor].[Kategori]","[Varderade_nyttor].[Kategori].&[Omfördelning ↺]"),0) -> 0 | E18: =IFERROR(GETPIVOTDATA("[Measures].[Sum of Troligt år "&($B18-$B$8+1)&" 4]",$F$40,"[Varderade_kostnader].[Kategori]","[Varderade_kostnader].[Kategori].&[Finansiell 💰]"),0) -> 0 | F18: =IFERROR(GETPIVOTDATA("[Measures].[Sum of Troligt år "&($B18-$B$8+1)&" 4]",$F$40,"[Varderade_kostnader].[Kategori]","[Varderade_kostnader].[Kategori].&[Omfördelning ↺]"),0) -> 0 | G18: =IF($B18="",NA(),SUM($C$8:C18)+SUM($D$8:D18)+SUM($E$8:E18)+SUM($F$8:F18)) -> 0
B19: =B18+1 -> 11 | C19: =IFERROR(GETPIVOTDATA("[Measures].[Sum of Troligt år "&($B19-$B$8+1)&" 3]",$B$40,"[Varderade_nyttor].[Kategori]","[Varderade_nyttor].[Kategori].&[Finansiell 💰]"),0) -> 0 | D19: =IFERROR(GETPIVOTDATA("[Measures].[Sum of Troligt år "&($B19-$B$8+1)&" 3]",$B$40,"[Varderade_nyttor].[Kategori]","[Varderade_nyttor].[Kategori].&[Omfördelning ↺]"),0) -> 0 | E19: =IFERROR(GETPIVOTDATA("[Measures].[Sum of Troligt år "&($B19-$B$8+1)&" 4]",$F$40,"[Varderade_kostnader].[Kategori]","[Varderade_kostnader].[Kategori].&[Finansiell 💰]"),0) -> 0 | F19: =IFERROR(GETPIVOTDATA("[Measures].[Sum of Troligt år "&($B19-$B$8+1)&" 4]",$F$40,"[Varderade_kostnader].[Kategori]","[Varderade_kostnader].[Kategori].&[Omfördelning ↺]"),0) -> 0 | G19: =IF($B19="",NA(),SUM($C$8:C19)+SUM($D$8:D19)+SUM($E$8:E19)+SUM($F$8:F19)) -> 0
B20: =B19+1 -> 12 | C20: =IFERROR(GETPIVOTDATA("[Measures].[Sum of Troligt år "&($B20-$B$8+1)&" 3]",$B$40,"[Varderade_nyttor].[Kategori]","[Varderade_nyttor].[Kategori].&[Finansiell 💰]"),0) -> 0 | D20: =IFERROR(GETPIVOTDATA("[Measures].[Sum of Troligt år "&($B20-$B$8+1)&" 3]",$B$40,"[Varderade_nyttor].[Kategori]","[Varderade_nyttor].[Kategori].&[Omfördelning ↺]"),0) -> 0 | E20: =IFERROR(GETPIVOTDATA("[Measures].[Sum of Troligt år "&($B20-$B$8+1)&" 4]",$F$40,"[Varderade_kostnader].[Kategori]","[Varderade_kostnader].[Kategori].&[Finansiell 💰]"),0) -> 0 | F20: =IFERROR(GETPIVOTDATA("[Measures].[Sum of Troligt år "&($B20-$B$8+1)&" 4]",$F$40,"[Varderade_kostnader].[Kategori]","[Varderade_kostnader].[Kategori].&[Omfördelning ↺]"),0) -> 0 | G20: =IF($B20="",NA(),SUM($C$8:C20)+SUM($D$8:D20)+SUM($E$8:E20)+SUM($F$8:F20)) -> 0
... B32: =B31+1 -> 24 | C32: =IFERROR(GETPIVOTDATA("[Measures].[Sum of Troligt år "&($B32-$B$8+1)&" 3]",$B$40,"[Varderade_nyttor].[Kategori]","[Varderade_nyttor].[Kategori].&[Finansiell 💰]"),0) -> 0 | D32: =IFERROR(GETPIVOTDATA("[Measures].[Sum of Troligt år "&($B32-$B$8+1)&" 3]",$B$40,"[Varderade_nyttor].[Kategori]","[Varderade_nyttor].[Kategori].&[Omfördelning ↺]"),0) -> 0 | E32: =IFERROR(GETPIVOTDATA("[Measures].[Sum of Troligt år "&($B32-$B$8+1)&" 4]",$F$40,"[Varderade_kostnader].[Kategori]","[Varderade_kostnader].[Kategori].&[Finansiell 💰]"),0) -> 0 | F32: =IFERROR(GETPIVOTDATA("[Measures].[Sum of Troligt år "&($B32-$B$8+1)&" 4]",$F$40,"[Varderade_kostnader].[Kategori]","[Varderade_kostnader].[Kategori].&[Omfördelning ↺]"),0) -> 0 | G32: =IF($B32="",NA(),SUM($C$8:C32)+SUM($D$8:D32)+SUM($E$8:E32)+SUM($F$8:F32)) -> 0
B33: SUMMA | C33: =SUM(C8:C32) -> 0 | D33: =SUM(D8:D32) -> 0 | E33: =SUM(E8:E32) -> 0 | F33: =SUM(F8:F32) -> 0
B35: SUMMA NYTTA | C35: =SUM(C33:D33) -> 0
B36: SUMMA KOSTNAD | C36: =-SUM(E33:F33) -> 0
B37: SAMMANLAGD NETTONYTTA | C37: =G32 -> 0
B38: NETTONYTTA PER SATSAD KRONA | C38: =IFERROR(C37/C36,0) -> 0
C40: Column Labels | G40: Column Labels
B41: Values | F41: Values
B42: Sum of Troligt år 1 | F42: Sum of Troligt år 1
B43: Sum of Troligt år 2 | F43: Sum of Troligt år 2
B44: Sum of Troligt år 3 | F44: Sum of Troligt år 3
B45: Sum of Troligt år 4 | F45: Sum of Troligt år 4
B46: Sum of Troligt år 5 | F46: Sum of Troligt år 5
B47: Sum of Troligt år 6 | F47: Sum of Troligt år 6
B48: Sum of Troligt år 7 | F48: Sum of Troligt år 7
B49: Sum of Troligt år 8 | F49: Sum of Troligt år 8
B50: Sum of Troligt år 9 | F50: Sum of Troligt år 9
B51: Sum of Troligt år 10 | F51: Sum of Troligt år 10
B52: Sum of Troligt år 11 | F52: Sum of Troligt år 11
... B66: Sum of Troligt år 25 | F66: Sum of Troligt år 25
B70: Underlag till andelen finansiella/omfördelning i tabell: sammanfattning
B73: Row Labels | C73: Sum of Summa | E73: Row Labels | F73: Sum of Summa
B80: Underlag till andel värderade nyttor och kostnader i tabell: sammanfattning
...

Sheet Input
B1: Input
B3: Kategorier | D3: Ej värderade | G3: Diskonteringsfaktorer
B4: ="Kvalitet " & _xlfn.UNICHAR(128420) -> Kvalitet 🖤 | D4: Stor ●●● | E4: 3 | G4: =Startar+COLUMNS($G:G)-1 -> 0 | H4: =Startar+COLUMNS($G:H)-1 -> 1 | I4: =Startar+COLUMNS($G:I)-1 -> 2 | J4: =Startar+COLUMNS($G:J)-1 -> 3 | K4: =Startar+COLUMNS($G:K)-1 -> 4 | L4: =Startar+COLUMNS($G:L)-1 -> 5 | M4: =Startar+COLUMNS($G:M)-1 -> 6 | N4: =Startar+COLUMNS($G:N)-1 -> 7 | O4: =Startar+COLUMNS($G:O)-1 -> 8 | P4: =Startar+COLUMNS($G:P)-1 -> 9 | Q4: =Startar+COLUMNS($G:Q)-1 -> 10 | R4: =Startar+COLUMNS($G:R)-1 -> 11 | S4: =Startar+COLUMNS($G:S)-1 -> 12 | T4: =Startar+COLUMNS($G:T)-1 -> 13 | U4: =Startar+COLUMNS($G:U)-1 -> 14 | V4: =Startar+COLUMNS($G:V)-1 -> 15 | W4: =Startar+COLUMNS($G:W)-1 -> 16 | X4: =Startar+COLUMNS($G:X)-1 -> 17 | Y4: =Startar+COLUMNS($G:Y)-1 -> 18 | Z4: =Startar+COLUMNS($G:Z)-1 -> 19 | AA4: =Startar+COLUMNS($G:AA)-1 -> 20 | AB4: =Startar+COLUMNS($G:AB)-1 -> 21 | AC4: =Startar+COLUMNS($G:AC)-1 -> 22 | AD4: =Startar+COLUMNS($G:AD)-1 -> 23 | AE4: =Startar+COLUMNS($G:AE)-1 -> 24
B5: Miljö 🍃 | D5: Måttlig ●● | E5: 2 | G5: =(1+Resultat!$O$2)^0 -> 1 | H5: =(1+Resultat!$O$2)^1 -> 1.03 | I5: =(1+Resultat!$O$2)^2 -> 1.0609 | J5: =(1+Resultat!$O$2)^3 -> 1.092727 | K5: =(1+Resultat!$O$2)^4 -> 1.1255088 | L5: =(1+Resultat!$O$2)^5 -> 1.1592741 | M5: =(1+Resultat!$O$2)^6 -> 1.1940523 | N5: =(1+Resultat!$O$2)^7 -> 1.2298739 | O5: =(1+Resultat!$O$2)^8 -> 1.2667701 | P5: =(1+Resultat!$O$2)^9 -> 1.3047732 | Q5: =(1+Resultat!$O$2)^10 -> 1.3439164 | R5: =(1+Resultat!$O$2)^11 -> 1.3842339 | S5: =(1+Resultat!$O$2)^12 -> 1.4257609 | T5: =(1+Resultat!$O$2)^13 -> 1.4685337 | U5: =(1+Resultat!$O$2)^14 -> 1.5125897 | V5: =(1+Resultat!$O$2)^15 -> 1.5579674 | W5: =(1+Resultat!$O$2)^16 -> 1.6047064 | X5: =(1+Resultat!$O$2)^17 -> 1.6528476 | Y5: =(1+Resultat!$O$2)^18 -> 1.7024331 | Z5: =(1+Resultat!$O$2)^19 -> 1.7535061 | AA5: =(1+Resultat!$O$2)^20 -> 1.8061112 | AB5: =(1+Resultat!$O$2)^21 -> 1.8602946 | AC5: =(1+Resultat!$O$2)^22 -> 1.9161034 | AD5: =(1+Resultat!$O$2)^23 -> 1.9735865 | AE5: =(1+Resultat!$O$2)^24 -> 2.0327941
B6: ="Omfördelning " & _xlfn.UNICHAR(8634) -> Omfördelning ↺ | D6: Liten ● | E6: 1
B7: ="Finansiell " & _xlfn.UNICHAR(128176) -> Finansiell 💰
B10: Tidshorisont i mallen
B11: 25 år

Sheet AN
A1: NID | B1: Rad NID uppe | C1: Rad NID nere | D1: Nytta | E1: Intressent | F1: Kategori | G1: Värdering | H1: Bedömning | I1: Bedömning siffra | J1: Troligt år 1 | K1: Troligt år 2 | L1: Troligt år 3 | M1: Troligt år 4 | N1: Troligt år 5 | O1: Troligt år 6 | P1: Troligt år 7 | Q1: Troligt år 8 | R1: Troligt år 9 | S1: Troligt år 10 | T1: Troligt år 11 | U1: Troligt år 12 | V1: Troligt år 13 | W1: Troligt år 14 | X1: Troligt år 15 | Y1: Troligt år 16 | Z1: Troligt år 17 | AA1: Troligt år 18 | AB1: Troligt år 19 | AC1: Troligt år 20 | AD1: Troligt år 21 | AE1: Troligt år 22 | AF1: Troligt år 23 | AG1: Troligt år 24 | AH1: Troligt år 25 | AI1: Summa | AJ1: Min år 1 | AK1: Min år 2 | AL1: Min år 3 | AM1: Min år 4 | AN1: Min år 5 | AO1: Min år 6 | AP1: Min år 7 | AQ1: Min år 8 | AR1: Min år 9 | AS1: Min år 10 | AT1: Min år 11 | AU1: Min år 12 | AV1: Min år 13 | AW1: Min år 14 | AX1: Min år 15 | AY1: Min år 16 | AZ1: Min år 17 | BA1: Min år 18 | BB1: Min år 19 | BC1: Min år 20 | BD1: Min år 21 | BE1: Min år 22 | BF1: Min år 23 | BG1: Min år 24 | BH1: Min år 25 | BI1: Summa min | BJ1: Max år 1 | BK1: Max år 2 | BL1: Max år 3 | BM1: Max år 4 | BN1: Max år 5 | BO1: Max år 6 | BP1: Max år 7 | BQ1: Max år 8 | BR1: Max år 9 | BS1: Max år 10 | BT1: Max år 11 | BU1: Max år 12 | BV1: Max år 13 | BW1: Max år 14 | BX1: Max år 15 | BY1: Max år 16 | BZ1: Max år 17 | CA1: Max år 18 | CB1: Max år 19 | CC1: Max år 20 | CD1: Max år 21 | CE1: Max år 22 | CF1: Max år 23 | CG1: Max år 24 | CH1: Max år 25 | CI1: Summa max
A2: ="N"&TEXT(ROWS($A$2:A2),"00") -> N01 | B2: =IFERROR(_xlfn.XMATCH($A2,'Värde nyttor'!$B:$B,0),"") -> 12 | C2: =IFERROR(_xlfn.XMATCH($A2,'Värde nyttor'!$I:$I,0),"") -> 23 | D2: {=IFERROR(INDEX('Värde nyttor'!$C:$C,$B2),"")} -> 0 | E2: {=IFERROR(INDEX('Värde nyttor'!$C:$C,$B2+1),"")} -> 0 | F2: {=IFERROR(INDEX('Värde nyttor'!$C:$C,$B2+2),"")} -> 0 | G2: =IF($D2=0,"","Värderad") | J2: {=IFERROR(INDEX('Värde nyttor'!$J:$AH,$C2+1,COLUMNS($J:J))/INDEX(Input!$G$5:$AE$5,COLUMNS($J:J)),"")} -> 0 | K2: {=IFERROR(INDEX('Värde nyttor'!$J:$AH,$C2+1,COLUMNS($J:K))/INDEX(Input!$G$5:$AE$5,COLUMNS($J:K)),"")} -> 0 | L2: {=IFERROR(INDEX('Värde nyttor'!$J:$AH,$C2+1,COLUMNS($J:L))/INDEX(Input!$G$5:$AE$5,COLUMNS($J:L)),"")} -> 0 | M2: {=IFERROR(INDEX('Värde nyttor'!$J:$AH,$C2+1,COLUMNS($J:M))/INDEX(Input!$G$5:$AE$5,COLUMNS($J:M)),"")} -> 0 | N2: {=IFERROR(INDEX('Värde nyttor'!$J:$AH,$C2+1,COLUMNS($J:N))/INDEX(Input!$G$5:$AE$5,COLUMNS($J:N)),"")} -> 0 | O2: {=IFERROR(INDEX('Värde nyttor'!$J:$AH,$C2+1,COLUMNS($J:O))/INDEX(Input!$G$5:$AE$5,COLUMNS($J:O)),"")} -> 0 | P2: {=IFERROR(INDEX('Värde nyttor'!$J:$AH,$C2+1,COLUMNS($J:P))/INDEX(Input!$G$5:$AE$5,COLUMNS($J:P)),"")} -> 0 | Q2: {=IFERROR(INDEX('Värde nyttor'!$J:$AH,$C2+1,COLUMNS($J:Q))/INDEX(Input!$G$5:$AE$5,COLUMNS($J:Q)),"")} -> 0 | R2: {=IFERROR(INDEX('Värde nyttor'!$J:$AH,$C2+1,COLUMNS($J:R))/INDEX(Input!$G$5:$AE$5,COLUMNS($J:R)),"")} -> 0 | S2: {=IFERROR(INDEX('Värde nyttor'!$J:$AH,$C2+1,COLUMNS($J:S))/INDEX(Input!$G$5:$AE$5,COLUMNS($J:S)),"")} -> 0 | T2: {=IFERROR(INDEX('Värde nyttor'!$J:$AH,$C2+1,COLUMNS($J:T))/INDEX(Input!$G$5:$AE$5,COLUMNS($J:T)),"")} -> 0 | U2: {=IFERROR(INDEX('Värde nyttor'!$J:$AH,$C2+1,COLUMNS($J:U))/INDEX(Input!$G$5:$AE$5,COLUMNS($J:U)),"")} -> 0 | V2: {=IFERROR(INDEX('Värde nyttor'!$J:$AH,$C2+1,COLUMNS($J:V))/INDEX(Input!$G$5:$AE$5,COLUMNS($J:V)),"")} -> 0 | W2: {=IFERROR(INDEX('Värde nyttor'!$J:$AH,$C2+1,COLUMNS($J:W))/INDEX(Input!$G$5:$AE$5,COLUMNS($J:W)),"")} -> 0 | X2: {=IFERROR(INDEX('Värde nyttor'!$J:$AH,$C2+1,COLUMNS($J:X))/INDEX(Input!$G$5:$AE$5,COLUMNS($J:X)),"")} -> 0 | Y2: {=IFERROR(INDEX('Värde nyttor'!$J:$AH,$C2+1,COLUMNS($J:Y))/INDEX(Input!$G$5:$AE$5,COLUMNS($J:Y)),"")} -> 0 | Z2: {=IFERROR(INDEX('Värde nyttor'!$J:$AH,$C2+1,COLUMNS($J:Z))/INDEX(Input!$G$5:$AE$5,COLUMNS($J:Z)),"")} -> 0 | AA2: {=IFERROR(INDEX('Värde nyttor'!$J:$AH,$C2+1,COLUMNS($J:AA))/INDEX(Input!$G$5:$AE$5,COLUMNS($J:AA)),"")} -> 0 | AB2: {=IFERROR(INDEX('Värde nyttor'!$J:$AH,$C2+1,COLUMNS($J:AB))/INDEX(Input!$G$5:$AE$5,COLUMNS($J:AB)),"")} -> 0 | AC2: {=IFERROR(INDEX('Värde nyttor'!$J:$AH,$C2+1,COLUMNS($J:AC))/INDEX(Input!$G$5:$AE$5,COLUMNS($J:AC)),"")} -> 0 | AD2: {=IFERROR(INDEX('Värde nyttor'!$J:$AH,$C2+1,COLUMNS($J:AD))/INDEX(Input!$G$5:$AE$5,COLUMNS($J:AD)),"")} -> 0 | AE2: {=IFERROR(INDEX('Värde nyttor'!$J:$AH,$C2+1,COLUMNS($J:AE))/INDEX(Input!$G$5:$AE$5,COLUMNS($J:AE)),"")} -> 0 | AF2: {=IFERROR(INDEX('Värde nyttor'!$J:$AH,$C2+1,COLUMNS($J:AF))/INDEX(Input!$G$5:$AE$5,COLUMNS($J:AF)),"")} -> 0 | AG2: {=IFERROR(INDEX('Värde nyttor'!$J:$AH,$C2+1,COLUMNS($J:AG))/INDEX(Input!$G$5:$AE$5,COLUMNS($J:AG)),"")} -> 0 | AH2: {=IFERROR(INDEX('Värde nyttor'!$J:$AH,$C2+1,COLUMNS($J:AH))/INDEX(Input!$G$5:$AE$5,COLUMNS($J:AH)),"")} -> 0 | AI2: =SUM(J2:AH2) -> 0 | AJ2: {=IFERROR(INDEX('Värde nyttor'!$J:$AH,$C2+2,COLUMNS($J:J))/INDEX(Input!$G$5:$AE$5,COLUMNS($J:J)),"")} -> 0 | AK2: {=IFERROR(INDEX('Värde nyttor'!$J:$AH,$C2+2,COLUMNS($J:K))/INDEX(Input!$G$5:$AE$5,COLUMNS($J:K)),"")} -> 0 | AL2: {=IFERROR(INDEX('Värde nyttor'!$J:$AH,$C2+2,COLUMNS($J:L))/INDEX(Input!$G$5:$AE$5,COLUMNS($J:L)),"")} -> 0 | AM2: {=IFERROR(INDEX('Värde nyttor'!$J:$AH,$C2+2,COLUMNS($J:M))/INDEX(Input!$G$5:$AE$5,COLUMNS($J:M)),"")} -> 0 | AN2: {=IFERROR(INDEX('Värde nyttor'!$J:$AH,$C2+2,COLUMNS($J:N))/INDEX(Input!$G$5:$AE$5,COLUMNS($J:N)),"")} -> 0 | AO2: {=IFERROR(INDEX('Värde nyttor'!$J:$AH,$C2+2,COLUMNS($J:O))/INDEX(Input!$G$5:$AE$5,COLUMNS($J:O)),"")} -> 0 | AP2: {=IFERROR(INDEX('Värde nyttor'!$J:$AH,$C2+2,COLUMNS($J:P))/INDEX(Input!$G$5:$AE$5,COLUMNS($J:P)),"")} -> 0 | AQ2: {=IFERROR(INDEX('Värde nyttor'!$J:$AH,$C2+2,COLUMNS($J:Q))/INDEX(Input!$G$5:$AE$5,COLUMNS($J:Q)),"")} -> 0 | AR2: {=IFERROR(INDEX('Värde nyttor'!$J:$AH,$C2+2,COLUMNS($J:R))/INDEX(Input!$G$5:$AE$5,COLUMNS($J:R)),"")} -> 0 | AS2: {=IFERROR(INDEX('Värde nyttor'!$J:$AH,$C2+2,COLUMNS($J:S))/INDEX(Input!$G$5:$AE$5,COLUMNS($J:S)),"")} -> 0 | AT2: {=IFERROR(INDEX('Värde nyttor'!$J:$AH,$C2+2,COLUMNS($J:T))/INDEX(Input!$G$5:$AE$5,COLUMNS($J:T)),"")} -> 0 | AU2: {=IFERROR(INDEX('Värde nyttor'!$J:$AH,$C2+2,COLUMNS($J:U))/INDEX(Input!$G$5:$AE$5,COLUMNS($J:U)),"")} -> 0 | AV2: {=IFERROR(INDEX('Värde nyttor'!$J:$AH,$C2+2,COLUMNS($J:V))/INDEX(Input!$G$5:$AE$5,COLUMNS($J:V)),"")} -> 0 | AW2: {=IFERROR(INDEX('Värde nyttor'!$J:$AH,$C2+2,COLUMNS($J:W))/INDEX(Input!$G$5:$AE$5,COLUMNS($J:W)),"")} -> 0 | AX2: {=IFERROR(INDEX('Värde nyttor'!$J:$AH,$C2+2,COLUMNS($J:X))/INDEX(Input!$G$5:$AE$5,COLUMNS($J:X)),"")} -> 0 | AY2: {=IFERROR(INDEX('Värde nyttor'!$J:$AH,$C2+2,COLUMNS($J:Y))/INDEX(Input!$G$5:$AE$5,COLUMNS($J:Y)),"")} -> 0 | AZ2: {=IFERROR(INDEX('Värde nyttor'!$J:$AH,$C2+2,COLUMNS($J:Z))/INDEX(Input!$G$5:$AE$5,COLUMNS($J:Z)),"")} -> 0 | BA2: {=IFERROR(INDEX('Värde nyttor'!$J:$AH,$C2+2,COLUMNS($J:AA))/INDEX(Input!$G$5:$AE$5,COLUMNS($J:AA)),"")} -> 0 | BB2: {=IFERROR(INDEX('Värde nyttor'!$J:$AH,$C2+2,COLUMNS($J:AB))/INDEX(Input!$G$5:$AE$5,COLUMNS($J:AB)),"")} -> 0 | BC2: {=IFERROR(INDEX('Värde nyttor'!$J:$AH,$C2+2,COLUMNS($J:AC))/INDEX(Input!$G$5:$AE$5,COLUMNS($J:AC)),"")} -> 0 | BD2: {=IFERROR(INDEX('Värde nyttor'!$J:$AH,$C2+2,COLUMNS($J:AD))/INDEX(Input!$G$5:$AE$5,COLUMNS($J:AD)),"")} -> 0 | BE2: {=IFERROR(INDEX('Värde nyttor'!$J:$AH,$C2+2,COLUMNS($J:AE))/INDEX(Input!$G$5:$AE$5,COLUMNS($J:AE)),"")} -> 0 | BF2: {=IFERROR(INDEX('Värde nyttor'!$J:$AH,$C2+2,COLUMNS($J:AF))/INDEX(Input!$G$5:$AE$5,COLUMNS($J:AF)),"")} -> 0 | BG2: {=IFERROR(INDEX('Värde nyttor'!$J:$AH,$C2+2,COLUMNS($J:AG))/INDEX(Input!$G$5:$AE$5,COLUMNS($J:AG)),"")} -> 0 | BH2: {=IFERROR(INDEX('Värde nyttor'!$J:$AH,$C2+2,COLUMNS($J:AH))/INDEX(Input!$G$5:$AE$5,COLUMNS($J:AH)),"")} -> 0 | BI2: =SUM(AJ2:BH2) -> 0 | BJ2: {=IFERROR(INDEX('Värde nyttor'!$J:$AH,$C2+3,COLUMNS($J:J))/INDEX(Input!$G$5:$AE$5,COLUMNS($J:J)),"")} -> 0 | BK2: {=IFERROR(INDEX('Värde nyttor'!$J:$AH,$C2+3,COLUMNS($J:K))/INDEX(Input!$G$5:$AE$5,COLUMNS($J:K)),"")} -> 0 | BL2: {=IFERROR(INDEX('Värde nyttor'!$J:$AH,$C2+3,COLUMNS($J:L))/INDEX(Input!$G$5:$AE$5,COLUMNS($J:L)),"")} -> 0 | BM2: {=IFERROR(INDEX('Värde nyttor'!$J:$AH,$C2+3,COLUMNS($J:M))/INDEX(Input!$G$5:$AE$5,COLUMNS($J:M)),"")} -> 0 | BN2: {=IFERROR(INDEX('Värde nyttor'!$J:$AH,$C2+3,COLUMNS($J:N))/INDEX(Input!$G$5:$AE$5,COLUMNS($J:N)),"")} -> 0 | BO2: {=IFERROR(INDEX('Värde nyttor'!$J:$AH,$C2+3,COLUMNS($J:O))/INDEX(Input!$G$5:$AE$5,COLUMNS($J:O)),"")} -> 0 | BP2: {=IFERROR(INDEX('Värde nyttor'!$J:$AH,$C2+3,COLUMNS($J:P))/INDEX(Input!$G$5:$AE$5,COLUMNS($J:P)),"")} -> 0 | BQ2: {=IFERROR(INDEX('Värde nyttor'!$J:$AH,$C2+3,COLUMNS($J:Q))/INDEX(Input!$G$5:$AE$5,COLUMNS($J:Q)),"")} -> 0 | BR2: {=IFERROR(INDEX('Värde nyttor'!$J:$AH,$C2+3,COLUMNS($J:R))/INDEX(Input!$G$5:$AE$5,COLUMNS($J:R)),"")} -> 0 | BS2: {=IFERROR(INDEX('Värde nyttor'!$J:$AH,$C2+3,COLUMNS($J:S))/INDEX(Input!$G$5:$AE$5,COLUMNS($J:S)),"")} -> 0 | BT2: {=IFERROR(INDEX('Värde nyttor'!$J:$AH,$C2+3,COLUMNS($J:T))/INDEX(Input!$G$5:$AE$5,COLUMNS($J:T)),"")} -> 0 | BU2: {=IFERROR(INDEX('Värde nyttor'!$J:$AH,$C2+3,COLUMNS($J:U))/INDEX(Input!$G$5:$AE$5,COLUMNS($J:U)),"")} -> 0 | BV2: {=IFERROR(INDEX('Värde nyttor'!$J:$AH,$C2+3,COLUMNS($J:V))/INDEX(Input!$G$5:$AE$5,COLUMNS($J:V)),"")} -> 0 | BW2: {=IFERROR(INDEX('Värde nyttor'!$J:$AH,$C2+3,COLUMNS($J:W))/INDEX(Input!$G$5:$AE$5,COLUMNS($J:W)),"")} -> 0 | BX2: {=IFERROR(INDEX('Värde nyttor'!$J:$AH,$C2+3,COLUMNS($J:X))/INDEX(Input!$G$5:$AE$5,COLUMNS($J:X)),"")} -> 0 | BY2: {=IFERROR(INDEX('Värde nyttor'!$J:$AH,$C2+3,COLUMNS($J:Y))/INDEX(Input!$G$5:$AE$5,COLUMNS($J:Y)),"")} -> 0 | BZ2: {=IFERROR(INDEX('Värde nyttor'!$J:$AH,$C2+3,COLUMNS($J:Z))/INDEX(Input!$G$5:$AE$5,COLUMNS($J:Z)),"")} -> 0 | CA2: {=IFERROR(INDEX('Värde nyttor'!$J:$AH,$C2+3,COLUMNS($J:AA))/INDEX(Input!$G$5:$AE$5,COLUMNS($J:AA)),"")} -> 0 | CB2: {=IFERROR(INDEX('Värde nyttor'!$J:$AH,$C2+3,COLUMNS($J:AB))/INDEX(Input!$G$5:$AE$5,COLUMNS($J:AB)),"")} -> 0 | CC2: {=IFERROR(INDEX('Värde nyttor'!$J:$AH,$C2+3,COLUMNS($J:AC))/INDEX(Input!$G$5:$AE$5,COLUMNS($J:AC)),"")} -> 0 | CD2: {=IFERROR(INDEX('Värde nyttor'!$J:$AH,$C2+3,COLUMNS($J:AD))/INDEX(Input!$G$5:$AE$5,COLUMNS($J:AD)),"")} -> 0 | CE2: {=IFERROR(INDEX('Värde nyttor'!$J:$AH,$C2+3,COLUMNS($J:AE))/INDEX(Input!$G$5:$AE$5,COLUMNS($J:AE)),"")} -> 0 | CF2: {=IFERROR(INDEX('Värde nyttor'!$J:$AH,$C2+3,COLUMNS($J:AF))/INDEX(Input!$G$5:$AE$5,COLUMNS($J:AF)),"")} -> 0 | CG2: {=IFERROR(INDEX('Värde nyttor'!$J:$AH,$C2+3,COLUMNS($J:AG))/INDEX(Input!$G$5:$AE$5,COLUMNS($J:AG)),"")} -> 0 | CH2: {=IFERROR(INDEX('Värde nyttor'!$J:$AH,$C2+3,COLUMNS($J:AH))/INDEX(Input!$G$5:$AE$5,COLUMNS($J:AH)),"")} -> 0 | CI2: =SUM(BJ2:CH2) -> 0
A3: ="N"&TEXT(ROWS($A$2:A3),"00") -> N02 | B3: =IFERROR(_xlfn.XMATCH($A3,'Värde nyttor'!$B:$B,0),"") -> 31 | C3: =IFERROR(_xlfn.XMATCH($A3,'Värde nyttor'!$I:$I,0),"") -> 42 | D3: {=IFERROR(INDEX('Värde nyttor'!$C:$C,$B3),"")} -> 0 | E3: {=IFERROR(INDEX('Värde nyttor'!$C:$C,$B3+1),"")} -> 0 | F3: {=IFERROR(INDEX('Värde nyttor'!$C:$C,$B3+2),"")} -> 0 | G3: =IF($D3=0,"","Värderad") | J3: {=IFERROR(INDEX('Värde nyttor'!$J:$AH,$C3+1,COLUMNS($J:J))/INDEX(Input!$G$5:$AE$5,COLUMNS($J:J)),"")} -> 0 | K3: {=IFERROR(INDEX('Värde nyttor'!$J:$AH,$C3+1,COLUMNS($J:K))/INDEX(Input!$G$5:$AE$5,COLUMNS($J:K)),"")} -> 0 | L3: {=IFERROR(INDEX('Värde nyttor'!$J:$AH,$C3+1,COLUMNS($J:L))/INDEX(Input!$G$5:$AE$5,COLUMNS($J:L)),"")} -> 0 | M3: {=IFERROR(INDEX('Värde nyttor'!$J:$AH,$C3+1,COLUMNS($J:M))/INDEX(Input!$G$5:$AE$5,COLUMNS($J:M)),"")} -> 0 | N3: {=IFERROR(INDEX('Värde nyttor'!$J:$AH,$C3+1,COLUMNS($J:N))/INDEX(Input!$G$5:$AE$5,COLUMNS($J:N)),"")} -> 0 | O3: {=IFERROR(INDEX('Värde nyttor'!$J:$AH,$C3+1,COLUMNS($J:O))/INDEX(Input!$G$5:$AE$5,COLUMNS($J:O)),"")} -> 0 | P3: {=IFERROR(INDEX('Värde nyttor'!$J:$AH,$C3+1,COLUMNS($J:P))/INDEX(Input!$G$5:$AE$5,COLUMNS($J:P)),"")} -> 0 | Q3: {=IFERROR(INDEX('Värde nyttor'!$J:$AH,$C3+1,COLUMNS($J:Q))/INDEX(Input!$G$5:$AE$5,COLUMNS($J:Q)),"")} -> 0 | R3: {=IFERROR(INDEX('Värde nyttor'!$J:$AH,$C3+1,COLUMNS($J:R))/INDEX(Input!$G$5:$AE$5,COLUMNS($J:R)),"")} -> 0 | S3: {=IFERROR(INDEX('Värde nyttor'!$J:$AH,$C3+1,COLUMNS($J:S))/INDEX(Input!$G$5:$AE$5,COLUMNS($J:S)),"")} -> 0 | T3: {=IFERROR(INDEX('Värde nyttor'!$J:$AH,$C3+1,COLUMNS($J:T))/INDEX(Input!$G$5:$AE$5,COLUMNS($J:T)),"")} -> 0 | U3: {=IFERROR(INDEX('Värde nyttor'!$J:$AH,$C3+1,COLUMNS($J:U))/INDEX(Input!$G$5:$AE$5,COLUMNS($J:U)),"")} -> 0 | V3: {=IFERROR(INDEX('Värde nyttor'!$J:$AH,$C3+1,COLUMNS($J:V))/INDEX(Input!$G$5:$AE$5,COLUMNS($J:V)),"")} -> 0 | W3: {=IFERROR(INDEX('Värde nyttor'!$J:$AH,$C3+1,COLUMNS($J:W))/INDEX(Input!$G$5:$AE$5,COLUMNS($J:W)),"")} -> 0 | X3: {=IFERROR(INDEX('Värde nyttor'!$J:$AH,$C3+1,COLUMNS($J:X))/INDEX(Input!$G$5:$AE$5,COLUMNS($J:X)),"")} -> 0 | Y3: {=IFERROR(INDEX('Värde nyttor'!$J:$AH,$C3+1,COLUMNS($J:Y))/INDEX(Input!$G$5:$AE$5,COLUMNS($J:Y)),"")} -> 0 | Z3: {=IFERROR(INDEX('Värde nyttor'!$J:$AH,$C3+1,COLUMNS($J:Z))/INDEX(Input!$G$5:$AE$5,COLUMNS($J:Z)),"")} -> 0 | AA3: {=IFERROR(INDEX('Värde nyttor'!$J:$AH,$C3+1,COLUMNS($J:AA))/INDEX(Input!$G$5:$AE$5,COLUMNS($J:AA)),"")} -> 0 | AB3: {=IFERROR(INDEX('Värde nyttor'!$J:$AH,$C3+1,COLUMNS($J:AB))/INDEX(Input!$G$5:$AE$5,COLUMNS($J:AB)),"")} -> 0 | AC3: {=IFERROR(INDEX('Värde nyttor'!$J:$AH,$C3+1,COLUMNS($J:AC))/INDEX(Input!$G$5:$AE$5,COLUMNS($J:AC)),"")} -> 0 | AD3: {=IFERROR(INDEX('Värde nyttor'!$J:$AH,$C3+1,COLUMNS($J:AD))/INDEX(Input!$G$5:$AE$5,COLUMNS($J:AD)),"")} -> 0 | AE3: {=IFERROR(INDEX('Värde nyttor'!$J:$AH,$C3+1,COLUMNS($J:AE))/INDEX(Input!$G$5:$AE$5,COLUMNS($J:AE)),"")} -> 0 | AF3: {=IFERROR(INDEX('Värde nyttor'!$J:$AH,$C3+1,COLUMNS($J:AF))/INDEX(Input!$G$5:$AE$5,COLUMNS($J:AF)),"")} -> 0 | AG3: {=IFERROR(INDEX('Värde nyttor'!$J:$AH,$C3+1,COLUMNS($J:AG))/INDEX(Input!$G$5:$AE$5,COLUMNS($J:AG)),"")} -> 0 | AH3: {=IFERROR(INDEX('Värde nyttor'!$J:$AH,$C3+1,COLUMNS($J:AH))/INDEX(Input!$G$5:$AE$5,COLUMNS($J:AH)),"")} -> 0 | AI3: =SUM(J3:AH3) -> 0 | AJ3: {=IFERROR(INDEX('Värde nyttor'!$J:$AH,$C3+2,COLUMNS($J:J))/INDEX(Input!$G$5:$AE$5,COLUMNS($J:J)),"")} -> 0 | AK3: {=IFERROR(INDEX('Värde nyttor'!$J:$AH,$C3+2,COLUMNS($J:K))/INDEX(Input!$G$5:$AE$5,COLUMNS($J:K)),"")} -> 0 | AL3: {=IFERROR(INDEX('Värde nyttor'!$J:$AH,$C3+2,COLUMNS($J:L))/INDEX(Input!$G$5:$AE$5,COLUMNS($J:L)),"")} -> 0 | AM3: {=IFERROR(INDEX('Värde nyttor'!$J:$AH,$C3+2,COLUMNS($J:M))/INDEX(Input!$G$5:$AE$5,COLUMNS($J:M)),"")} -> 0 | AN3: {=IFERROR(INDEX('Värde nyttor'!$J:$AH,$C3+2,COLUMNS($J:N))/INDEX(Input!$G$5:$AE$5,COLUMNS($J:N)),"")} -> 0 | AO3: {=IFERROR(INDEX('Värde nyttor'!$J:$AH,$C3+2,COLUMNS($J:O))/INDEX(Input!$G$5:$AE$5,COLUMNS($J:O)),"")} -> 0 | AP3: {=IFERROR(INDEX('Värde nyttor'!$J:$AH,$C3+2,COLUMNS($J:P))/INDEX(Input!$G$5:$AE$5,COLUMNS($J:P)),"")} -> 0 | AQ3: {=IFERROR(INDEX('Värde nyttor'!$J:$AH,$C3+2,COLUMNS($J:Q))/INDEX(Input!$G$5:$AE$5,COLUMNS($J:Q)),"")} -> 0 | AR3: {=IFERROR(INDEX('Värde nyttor'!$J:$AH,$C3+2,COLUMNS($J:R))/INDEX(Input!$G$5:$AE$5,COLUMNS($J:R)),"")} -> 0 | AS3: {=IFERROR(INDEX('Värde nyttor'!$J:$AH,$C3+2,COLUMNS($J:S))/INDEX(Input!$G$5:$AE$5,COLUMNS($J:S)),"")} -> 0 | AT3: {=IFERROR(INDEX('Värde nyttor'!$J:$AH,$C3+2,COLUMNS($J:T))/INDEX(Input!$G$5:$AE$5,COLUMNS($J:T)),"")} -> 0 | AU3: {=IFERROR(INDEX('Värde nyttor'!$J:$AH,$C3+2,COLUMNS($J:U))/INDEX(Input!$G$5:$AE$5,COLUMNS($J:U)),"")} -> 0 | AV3: {=IFERROR(INDEX('Värde nyttor'!$J:$AH,$C3+2,COLUMNS($J:V))/INDEX(Input!$G$5:$AE$5,COLUMNS($J:V)),"")} -> 0 | AW3: {=IFERROR(INDEX('Värde nyttor'!$J:$AH,$C3+2,COLUMNS($J:W))/INDEX(Input!$G$5:$AE$5,COLUMNS($J:W)),"")} -> 0 | AX3: {=IFERROR(INDEX('Värde nyttor'!$J:$AH,$C3+2,COLUMNS($J:X))/INDEX(Input!$G$5:$AE$5,COLUMNS($J:X)),"")} -> 0 | AY3: {=IFERROR(INDEX('Värde nyttor'!$J:$AH,$C3+2,COLUMNS($J:Y))/INDEX(Input!$G$5:$AE$5,COLUMNS($J:Y)),"")} -> 0 | AZ3: {=IFERROR(INDEX('Värde nyttor'!$J:$AH,$C3+2,COLUMNS($J:Z))/INDEX(Input!$G$5:$AE$5,COLUMNS($J:Z)),"")} -> 0 | BA3: {=IFERROR(INDEX('Värde nyttor'!$J:$AH,$C3+2,COLUMNS($J:AA))/INDEX(Input!$G$5:$AE$5,COLUMNS($J:AA)),"")} -> 0 | BB3: {=IFERROR(INDEX('Värde nyttor'!$J:$AH,$C3+2,COLUMNS($J:AB))/INDEX(Input!$G$5:$AE$5,COLUMNS($J:AB)),"")} -> 0 | BC3: {=IFERROR(INDEX('Värde nyttor'!$J:$AH,$C3+2,COLUMNS($J:AC))/INDEX(Input!$G$5:$AE$5,COLUMNS($J:AC)),"")} -> 0 | BD3: {=IFERROR(INDEX('Värde nyttor'!$J:$AH,$C3+2,COLUMNS($J:AD))/INDEX(Input!$G$5:$AE$5,COLUMNS($J:AD)),"")} -> 0 | BE3: {=IFERROR(INDEX('Värde nyttor'!$J:$AH,$C3+2,COLUMNS($J:AE))/INDEX(Input!$G$5:$AE$5,COLUMNS($J:AE)),"")} -> 0 | BF3: {=IFERROR(INDEX('Värde nyttor'!$J:$AH,$C3+2,COLUMNS($J:AF))/INDEX(Input!$G$5:$AE$5,COLUMNS($J:AF)),"")} -> 0 | BG3: {=IFERROR(INDEX('Värde nyttor'!$J:$AH,$C3+2,COLUMNS($J:AG))/INDEX(Input!$G$5:$AE$5,COLUMNS($J:AG)),"")} -> 0 | BH3: {=IFERROR(INDEX('Värde nyttor'!$J:$AH,$C3+2,COLUMNS($J:AH))/INDEX(Input!$G$5:$AE$5,COLUMNS($J:AH)),"")} -> 0 | BI3: =SUM(AJ3:BH3) -> 0 | BJ3: {=IFERROR(INDEX('Värde nyttor'!$J:$AH,$C3+3,COLUMNS($J:J))/INDEX(Input!$G$5:$AE$5,COLUMNS($J:J)),"")} -> 0 | BK3: {=IFERROR(INDEX('Värde nyttor'!$J:$AH,$C3+3,COLUMNS($J:K))/INDEX(Input!$G$5:$AE$5,COLUMNS($J:K)),"")} -> 0 | BL3: {=IFERROR(INDEX('Värde nyttor'!$J:$AH,$C3+3,COLUMNS($J:L))/INDEX(Input!$G$5:$AE$5,COLUMNS($J:L)),"")} -> 0 | BM3: {=IFERROR(INDEX('Värde nyttor'!$J:$AH,$C3+3,COLUMNS($J:M))/INDEX(Input!$G$5:$AE$5,COLUMNS($J:M)),"")} -> 0 | BN3: {=IFERROR(INDEX('Värde nyttor'!$J:$AH,$C3+3,COLUMNS($J:N))/INDEX(Input!$G$5:$AE$5,COLUMNS($J:N)),"")} -> 0 | BO3: {=IFERROR(INDEX('Värde nyttor'!$J:$AH,$C3+3,COLUMNS($J:O))/INDEX(Input!$G$5:$AE$5,COLUMNS($J:O)),"")} -> 0 | BP3: {=IFERROR(INDEX('Värde nyttor'!$J:$AH,$C3+3,COLUMNS($J:P))/INDEX(Input!$G$5:$AE$5,COLUMNS($J:P)),"")} -> 0 | BQ3: {=IFERROR(INDEX('Värde nyttor'!$J:$AH,$C3+3,COLUMNS($J:Q))/INDEX(Input!$G$5:$AE$5,COLUMNS($J:Q)),"")} -> 0 | BR3: {=IFERROR(INDEX('Värde nyttor'!$J:$AH,$C3+3,COLUMNS($J:R))/INDEX(Input!$G$5:$AE$5,COLUMNS($J:R)),"")} -> 0 | BS3: {=IFERROR(INDEX('Värde nyttor'!$J:$AH,$C3+3,COLUMNS($J:S))/INDEX(Input!$G$5:$AE$5,COLUMNS($J:S)),"")} -> 0 | BT3: {=IFERROR(INDEX('Värde nyttor'!$J:$AH,$C3+3,COLUMNS($J:T))/INDEX(Input!$G$5:$AE$5,COLUMNS($J:T)),"")} -> 0 | BU3: {=IFERROR(INDEX('Värde nyttor'!$J:$AH,$C3+3,COLUMNS($J:U))/INDEX(Input!$G$5:$AE$5,COLUMNS($J:U)),"")} -> 0 | BV3: {=IFERROR(INDEX('Värde nyttor'!$J:$AH,$C3+3,COLUMNS($J:V))/INDEX(Input!$G$5:$AE$5,COLUMNS($J:V)),"")} -> 0 | BW3: {=IFERROR(INDEX('Värde nyttor'!$J:$AH,$C3+3,COLUMNS($J:W))/INDEX(Input!$G$5:$AE$5,COLUMNS($J:W)),"")} -> 0 | BX3: {=IFERROR(INDEX('Värde nyttor'!$J:$AH,$C3+3,COLUMNS($J:X))/INDEX(Input!$G$5:$AE$5,COLUMNS($J:X)),"")} -> 0 | BY3: {=IFERROR(INDEX('Värde nyttor'!$J:$AH,$C3+3,COLUMNS($J:Y))/INDEX(Input!$G$5:$AE$5,COLUMNS($J:Y)),"")} -> 0 | BZ3: {=IFERROR(INDEX('Värde nyttor'!$J:$AH,$C3+3,COLUMNS($J:Z))/INDEX(Input!$G$5:$AE$5,COLUMNS($J:Z)),"")} -> 0 | CA3: {=IFERROR(INDEX('Värde nyttor'!$J:$AH,$C3+3,COLUMNS($J:AA))/INDEX(Input!$G$5:$AE$5,COLUMNS($J:AA)),"")} -> 0 | CB3: {=IFERROR(INDEX('Värde nyttor'!$J:$AH,$C3+3,COLUMNS($J:AB))/INDEX(Input!$G$5:$AE$5,COLUMNS($J:AB)),"")} -> 0 | CC3: {=IFERROR(INDEX('Värde nyttor'!$J:$AH,$C3+3,COLUMNS($J:AC))/INDEX(Input!$G$5:$AE$5,COLUMNS($J:AC)),"")} -> 0 | CD3: {=IFERROR(INDEX('Värde nyttor'!$J:$AH,$C3+3,COLUMNS($J:AD))/INDEX(Input!$G$5:$AE$5,COLUMNS($J:AD)),"")} -> 0 | CE3: {=IFERROR(INDEX('Värde nyttor'!$J:$AH,$C3+3,COLUMNS($J:AE))/INDEX(Input!$G$5:$AE$5,COLUMNS($J:AE)),"")} -> 0 | CF3: {=IFERROR(INDEX('Värde nyttor'!$J:$AH,$C3+3,COLUMNS($J:AF))/INDEX(Input!$G$5:$AE$5,COLUMNS($J:AF)),"")} -> 0 | CG3: {=IFERROR(INDEX('Värde nyttor'!$J:$AH,$C3+3,COLUMNS($J:AG))/INDEX(Input!$G$5:$AE$5,COLUMNS($J:AG)),"")} -> 0 | CH3: {=IFERROR(INDEX('Värde nyttor'!$J:$AH,$C3+3,COLUMNS($J:AH))/INDEX(Input!$G$5:$AE$5,COLUMNS($J:AH)),"")} -> 0 | CI3: =SUM(BJ3:CH3) -> 0
